Workbook

Sheet II IT
C1: Chennai Institute of Technology
C2: Sarathy Nagar, Pudupedu, Kundrathur, Chennai-600069
C3: 2025-26 Academic Year - ODD SEMESTER
C4: End Semester Result Analysis OCT/NOV 2025
A5: Year: II Semester:III Branch: IT Section: A,B&C | W5: =G7 -> EES | X5: =H7 -> CA | Y5: =I7 -> OS | Z5: =J7 -> DAA | AA5: =K7 -> AIML | AB5: =L7 -> PYTHON | AC5: {=M6:N7} -> IT4306 | AD5: MA4302 | AJ5: =W7+X7+Y7+Z7+AA7+AB7+AC7+AD7 -> 23
A6: Sno | B6: Reg No | C6: Name of the Students | D6: M/F | E6: H/D | F6: Cutoff | G6: ES4301 | H6: IT4301 | I6: IT4302 | J6: IT4303 | K6: IT4304 | L6: IT4305 | M6: IT4306 | N6: MA4302 | O6: Arr | P6: To. Arr | Q6: Cr. Ernd | R6: GPA | S6: CGPA | U6: FS/HS | V6: T/NT | W6: =G6 -> ES4301 | X6: =H6 -> IT4301 | Y6: =I6 -> IT4302 | Z6: =J6 -> IT4303 | AA6: =K6 -> IT4304 | AB6: =L6 -> IT4305 | AC6: CCP | AD6: DM | AG6: Numr | AH6: Credit earned | AI6: GPA | AJ6: P/F
G7: EES | H7: CA | I7: OS | J7: DAA | K7: AIML | L7: PYTHON | M7: CCP | N7: DM | W7: 1 | X7: 4 | Y7: 4 | Z7: 4 | AA7: 3 | AB7: 1 | AC7: 3 | AD7: 3 | AK7: 180 | AL7: 160 | AM7: 140 | AN7: 120 | AO7: 110 | AP7: 100 | AQ7: <100 | AS7: =AK7 -> 180 | AT7: =AL7 -> 160 | AU7: =AM7 -> 140 | AV7: =AN7 -> 120 | AW7: =AO7 -> 110 | AX7: =AP7 -> 100 | AY7: =AQ7 -> <100 | AZ7: H/D | BA7: T/NT | BB7: HM | BC7: HF | BD7: DM | BE7: DF | BG7: HM | BH7: HF | BI7: DM | BJ7: DF | BK7: M | BL7: F | BP7: HMT | BQ7: HFT | BR7: DMT | BS7: DFT | BT7: HMNT | BU7: HFNT | BV7: DMNT | BW7: DFNT | BY7: HMT | BZ7: HFT | CA7: DMT | CB7: DFT | CC7: HMNT | CD7: HFNT | CE7: DMNT | CF7: DFNT | CG7: M | CH7: F | CK7: =G6 -> ES4301 | CL7: =H6 -> IT4301 | CM7: =I6 -> IT4302 | CN7: =J6 -> IT4303 | CO7: =K6 -> IT4304 | CP7: =L6 -> IT4305 | CQ7: {=M6:N6} -> IT4306 | CR7: MA4302 | CT7: FAIL | CU7: =A6 -> Sno | CV7: =B6 -> Reg No | CW7: =C6 -> Name of the Students | CX7: NAME OF THE SUBJECT FAILED | CY7: TOTAL NO OF SUB FAIL | DA7: H | DB7: D
A8: 1 | B8: 24IT0001 | C8: ABARNA G | D8: F | E8: H | G8: O | H8: B+ | I8: O | J8: A+ | K8: O | L8: A | M8: O | N8: B+ | O8: =COUNTIF(G8:N8,"U")+COUNTIF(G8:N8,"UA")+COUNTIF(G8:N8,"WH") -> 0 | Q8: =AH8 -> 23 | R8: 8.68 | V8: T | W8: =IF(G8="O",10,IF(G8="A+",9,IF(G8="A",8,IF(G8="B+",7,IF(G8="B",6,IF(G8="C",5,IF(G8="RA",0,IF(G8="U",0,IF(G8="UA",0,0))))))))) -> 10 | X8: =IF(H8="O",10,IF(H8="A+",9,IF(H8="A",8,IF(H8="B+",7,IF(H8="B",6,IF(H8="C",5,IF(H8="RA",0,IF(H8="U",0,IF(H8="UA",0,0))))))))) -> 7 | Y8: =IF(I8="O",10,IF(I8="A+",9,IF(I8="A",8,IF(I8="B+",7,IF(I8="B",6,IF(I8="C",5,IF(I8="RA",0,IF(I8="U",0,IF(I8="UA",0,0))))))))) -> 10 | Z8: =IF(J8="O",10,IF(J8="A+",9,IF(J8="A",8,IF(J8="B+",7,IF(J8="B",6,IF(J8="C",5,IF(J8="RA",0,IF(J8="U",0,IF(J8="UA",0,0))))))))) -> 9 | AA8: =IF(K8="O",10,IF(K8="A+",9,IF(K8="A",8,IF(K8="B+",7,IF(K8="B",6,IF(K8="C",5,IF(K8="RA",0,IF(K8="U",0,IF(K8="UA",0,0))))))))) -> 10 | AB8: =IF(L8="O",10,IF(L8="A+",9,IF(L8="A",8,IF(L8="B+",7,IF(L8="B",6,IF(L8="C",5,IF(L8="RA",0,IF(L8="U",0,IF(L8="UA",0,0))))))))) -> 8 | AC8: =IF(M8="O",10,IF(M8="A+",9,IF(M8="A",8,IF(M8="B+",7,IF(M8="B",6,IF(M8="C",5,IF(M8="RA",0,IF(M8="U",0,IF(M8="UA",0,0))))))))) -> 10 | AD8: =IF(N8="O",10,IF(N8="A+",9,IF(N8="A",8,IF(N8="B+",7,IF(N8="B",6,IF(N8="C",5,IF(N8="RA",0,IF(N8="U",0,IF(N8="UA",0,0))))))))) -> 7 | AG8: =(W8*W$7)+(X8*X$7)+(Y8*Y$7)+(Z8*Z$7)+(AA8*AA$7)+(AB8*AB$7)+(AC8*AC$7)+(AD8*AD$7) -> 203 | AH8: =IF(W8=0,0,W$7)+IF(X8=0,0,X$7)+IF(Y8=0,0,Y$7)+IF(Z8=0,0,Z$7)+IF(AA8=0,0,AA$7)+IF(AB8=0,0,AB$7)+IF(AC8=0,0,AC$7)+IF(AD8=0,0,AD$7) -> 23 | AI8: =IF(AH8=0,0,AG8/AH8) -> 8.826087 | AJ8: =IF(AH8=23,"P","F") -> P | AK8: =IF(F8>179,1,0) -> 0 | AL8: =IF(F8>159,1,0)-AK8 -> 0 | AM8: =IF(F8>139,1,0)-(AK8+AL8) -> 0 | AN8: =IF(F8>119,1,0)-(AK8+AL8+AM8) -> 0 | AO8: =IF(F8>109,1,0)-(AK8+AL8+AM8+AN8) -> 0 | AP8: =IF(F8>=100,1,0)-(AK8+AL8+AM8+AN8+AO8) -> 0 | AQ8: =IF(F8<100,1,0) -> 1 | AS8: =IF(AK8=0,0,AJ8) -> 0 | AT8: =IF(AL8=0,0,AJ8) -> 0 | AU8: =IF(AM8=0,0,AJ8) -> 0 | AV8: =IF(AN8=0,0,AJ8) -> 0 | AW8: =IF(AO8=0,0,AJ8) -> 0 | AX8: =IF(AP8=0,0,AJ8) -> 0 | AY8: =IF(AQ8=0,0,AJ8) -> P | AZ8: =CONCATENATE(E8,D8) -> HF | BA8: =CONCATENATE(AZ8,V8) -> HFT | BB8: =IF(AZ8="HM",AJ8,"#") -> # | BC8: =IF(AZ8="HF",AJ8,"#") -> P | BD8: =IF(AZ8="DM",AJ8,"#") -> # | BE8: =IF(AZ8="DF",AJ8,"#") -> # | BG8: =IF(AZ8="HM",O8,"#") -> # | BH8: =IF(AZ8="HF",O8,"#") -> 0 | BI8: =IF(AZ8="DM",O8,"#") -> # | BJ8: =IF(AZ8="DF",O8,"#") -> # | BK8: =IF(D8="M",O8,"#") -> # | BL8: =IF(D8="F",O8,"#") -> 0 | BP8: =IF(BA8="HMT",AJ8,"#") -> # | BQ8: =IF(BA8="HFT",AJ8,"#") -> P | BR8: =IF(BA8="DMT",AJ8,"#") -> # | BS8: =IF(BA8="DFT",AJ8,"#") -> # | BT8: =IF(BA8="HMNT",AJ8,"#") -> # | BU8: =IF(BA8="HFNT",AJ8,"#") -> # | BV8: =IF(BA8="DMNT",AJ8,"#") -> # | BW8: =IF(BA8="DFNT",AJ8,"#") -> # | BY8: =IF(BA8="HMT",O8,"#") -> # | BZ8: =IF(BA8="HFT",O8,"#") -> 0 | CA8: =IF(BA8="DMT",O8,"#") -> # | CB8: =IF(BA8="DFT",O8,"#") -> # | CC8: =IF(BA8="HMNT",O8,"#") -> # | CD8: =IF(BA8="HFNT",O8,"#") -> # | CE8: =IF(BA8="DMNT",O8,"#") -> # | CF8: =IF(BA8="DFNT",O8,"#") -> # | CG8: =IF(D8="M",O8,"#") -> # | CH8: =IF(D8="F",O8,"#") -> 0 | CK8: =IF(W8=0,"EEP,"," ") | CL8: =IF(X8=0,"POC,"," ") | CM8: =IF(Y8=0,"DAV,"," ") | CN8: =IF(Z8=0,"EP,"," ") | CO8: =IF(AA8=0,"MAD,"," ") | CP8: =IF(AB8=0,"CCP,"," ") | CQ8: =IF(AC8=0,"UIUX,"," ") | CR8: =IF(AD8=0,"DEV,"," ") | CT8: =O8 -> 0 | CU8: =A8 -> 1 | CV8: =B8 -> 24IT0001 | CW8: =C8 -> ABARNA G | CX8: =CONCATENATE(CK8,CL8,CM8,CN8,CO8,CP8,CQ8,CR8,CS8) | CY8: =CT8 -> 0 | DA8: =IF(E8="H",O8,"#") -> 0 | DB8: =IF(E8="D",O8,"#") -> #
A9: 2 | B9: 24IT0002 | C9: ABHIJEETH V N | D9: M | E9: D | G9: O | H9: B+ | I9: A | J9: A+ | K9: O | L9: A | M9: O | N9: B+ | O9: =COUNTIF(G9:N9,"U")+COUNTIF(G9:N9,"UA")+COUNTIF(G9:N9,"WH") -> 0 | Q9: =AH9 -> 23 | R9: 8.36 | V9: T | W9: =IF(G9="O",10,IF(G9="A+",9,IF(G9="A",8,IF(G9="B+",7,IF(G9="B",6,IF(G9="C",5,IF(G9="RA",0,IF(G9="U",0,IF(G9="UA",0,0))))))))) -> 10 | X9: =IF(H9="O",10,IF(H9="A+",9,IF(H9="A",8,IF(H9="B+",7,IF(H9="B",6,IF(H9="C",5,IF(H9="RA",0,IF(H9="U",0,IF(H9="UA",0,0))))))))) -> 7 | Y9: =IF(I9="O",10,IF(I9="A+",9,IF(I9="A",8,IF(I9="B+",7,IF(I9="B",6,IF(I9="C",5,IF(I9="RA",0,IF(I9="U",0,IF(I9="UA",0,0))))))))) -> 8 | Z9: =IF(J9="O",10,IF(J9="A+",9,IF(J9="A",8,IF(J9="B+",7,IF(J9="B",6,IF(J9="C",5,IF(J9="RA",0,IF(J9="U",0,IF(J9="UA",0,0))))))))) -> 9 | AA9: =IF(K9="O",10,IF(K9="A+",9,IF(K9="A",8,IF(K9="B+",7,IF(K9="B",6,IF(K9="C",5,IF(K9="RA",0,IF(K9="U",0,IF(K9="UA",0,0))))))))) -> 10 | AB9: =IF(L9="O",10,IF(L9="A+",9,IF(L9="A",8,IF(L9="B+",7,IF(L9="B",6,IF(L9="C",5,IF(L9="RA",0,IF(L9="U",0,IF(L9="UA",0,0))))))))) -> 8 | AC9: =IF(M9="O",10,IF(M9="A+",9,IF(M9="A",8,IF(M9="B+",7,IF(M9="B",6,IF(M9="C",5,IF(M9="RA",0,IF(M9="U",0,IF(M9="UA",0,0))))))))) -> 10 | AD9: =IF(N9="O",10,IF(N9="A+",9,IF(N9="A",8,IF(N9="B+",7,IF(N9="B",6,IF(N9="C",5,IF(N9="RA",0,IF(N9="U",0,IF(N9="UA",0,0))))))))) -> 7 | AG9: =(W9*W$7)+(X9*X$7)+(Y9*Y$7)+(Z9*Z$7)+(AA9*AA$7)+(AB9*AB$7)+(AC9*AC$7)+(AD9*AD$7) -> 195 | AH9: =IF(W9=0,0,W$7)+IF(X9=0,0,X$7)+IF(Y9=0,0,Y$7)+IF(Z9=0,0,Z$7)+IF(AA9=0,0,AA$7)+IF(AB9=0,0,AB$7)+IF(AC9=0,0,AC$7)+IF(AD9=0,0,AD$7) -> 23 | AI9: =IF(AH9=0,0,AG9/AH9) -> 8.4782609 | AJ9: =IF(AH9=23,"P","F") -> P | AK9: =IF(F9>179,1,0) -> 0 | AL9: =IF(F9>159,1,0)-AK9 -> 0 | AM9: =IF(F9>139,1,0)-(AK9+AL9) -> 0 | AN9: =IF(F9>119,1,0)-(AK9+AL9+AM9) -> 0 | AO9: =IF(F9>109,1,0)-(AK9+AL9+AM9+AN9) -> 0 | AP9: =IF(F9>=100,1,0)-(AK9+AL9+AM9+AN9+AO9) -> 0 | AQ9: =IF(F9<100,1,0) -> 1 | AS9: =IF(AK9=0,0,AJ9) -> 0 | AT9: =IF(AL9=0,0,AJ9) -> 0 | AU9: =IF(AM9=0,0,AJ9) -> 0 | AV9: =IF(AN9=0,0,AJ9) -> 0 | AW9: =IF(AO9=0,0,AJ9) -> 0 | AX9: =IF(AP9=0,0,AJ9) -> 0 | AY9: =IF(AQ9=0,0,AJ9) -> P | AZ9: =CONCATENATE(E9,D9) -> DM | BA9: =CONCATENATE(AZ9,V9) -> DMT | BB9: =IF(AZ9="HM",AJ9,"#") -> # | BC9: =IF(AZ9="HF",AJ9,"#") -> # | BD9: =IF(AZ9="DM",AJ9,"#") -> P | BE9: =IF(AZ9="DF",AJ9,"#") -> # | BG9: =IF(AZ9="HM",O9,"#") -> # | BH9: =IF(AZ9="HF",O9,"#") -> # | BI9: =IF(AZ9="DM",O9,"#") -> 0 | BJ9: =IF(AZ9="DF",O9,"#") -> # | BK9: =IF(D9="M",O9,"#") -> 0 | BL9: =IF(D9="F",O9,"#") -> # | BP9: =IF(BA9="HMT",AJ9,"#") -> # | BQ9: =IF(BA9="HFT",AJ9,"#") -> # | BR9: =IF(BA9="DMT",AJ9,"#") -> P | BS9: =IF(BA9="DFT",AJ9,"#") -> # | BT9: =IF(BA9="HMNT",AJ9,"#") -> # | BU9: =IF(BA9="HFNT",AJ9,"#") -> # | BV9: =IF(BA9="DMNT",AJ9,"#") -> # | BW9: =IF(BA9="DFNT",AJ9,"#") -> # | BY9: =IF(BA9="HMT",O9,"#") -> # | BZ9: =IF(BA9="HFT",O9,"#") -> # | CA9: =IF(BA9="DMT",O9,"#") -> 0 | CB9: =IF(BA9="DFT",O9,"#") -> # | CC9: =IF(BA9="HMNT",O9,"#") -> # | CD9: =IF(BA9="HFNT",O9,"#") -> # | CE9: =IF(BA9="DMNT",O9,"#") -> # | CF9: =IF(BA9="DFNT",O9,"#") -> # | CG9: =IF(D9="M",O9,"#") -> 0 | CH9: =IF(D9="F",O9,"#") -> # | CK9: =IF(W9=0,"EEP,"," ") | CL9: =IF(X9=0,"POC,"," ") | CM9: =IF(Y9=0,"DAV,"," ") | CN9: =IF(Z9=0,"EP,"," ") | CO9: =IF(AA9=0,"MAD,"," ") | CP9: =IF(AB9=0,"CCP,"," ") | CQ9: =IF(AC9=0,"UIUX,"," ") | CR9: =IF(AD9=0,"DEV,"," ") | CT9: =O9 -> 0 | CU9: =A9 -> 2 | CV9: =B9 -> 24IT0002 | CW9: =C9 -> ABHIJEETH V N | CX9: =CONCATENATE(CK9,CL9,CM9,CN9,CO9,CP9,CQ9,CR9,CS9) | CY9: =CT9 -> 0 | DA9: =IF(E9="H",O9,"#") -> # | DB9: =IF(E9="D",O9,"#") -> 0
A10: 3 | B10: 24IT0003 | C10: ADITHYA A M | D10: M | E10: H | G10: O | H10: B+ | I10: A | J10: O | K10: O | L10: A | M10: O | N10: B+ | O10: =COUNTIF(G10:N10,"U")+COUNTIF(G10:N10,"UA")+COUNTIF(G10:N10,"WH") -> 0 | Q10: =AH10 -> 23 | R10: 8.52 | V10: T | W10: =IF(G10="O",10,IF(G10="A+",9,IF(G10="A",8,IF(G10="B+",7,IF(G10="B",6,IF(G10="C",5,IF(G10="RA",0,IF(G10="U",0,IF(G10="UA",0,0))))))))) -> 10 | X10: =IF(H10="O",10,IF(H10="A+",9,IF(H10="A",8,IF(H10="B+",7,IF(H10="B",6,IF(H10="C",5,IF(H10="RA",0,IF(H10="U",0,IF(H10="UA",0,0))))))))) -> 7 | Y10: =IF(I10="O",10,IF(I10="A+",9,IF(I10="A",8,IF(I10="B+",7,IF(I10="B",6,IF(I10="C",5,IF(I10="RA",0,IF(I10="U",0,IF(I10="UA",0,0))))))))) -> 8 | Z10: =IF(J10="O",10,IF(J10="A+",9,IF(J10="A",8,IF(J10="B+",7,IF(J10="B",6,IF(J10="C",5,IF(J10="RA",0,IF(J10="U",0,IF(J10="UA",0,0))))))))) -> 10 | AA10: =IF(K10="O",10,IF(K10="A+",9,IF(K10="A",8,IF(K10="B+",7,IF(K10="B",6,IF(K10="C",5,IF(K10="RA",0,IF(K10="U",0,IF(K10="UA",0,0))))))))) -> 10 | AB10: =IF(L10="O",10,IF(L10="A+",9,IF(L10="A",8,IF(L10="B+",7,IF(L10="B",6,IF(L10="C",5,IF(L10="RA",0,IF(L10="U",0,IF(L10="UA",0,0))))))))) -> 8 | AC10: =IF(M10="O",10,IF(M10="A+",9,IF(M10="A",8,IF(M10="B+",7,IF(M10="B",6,IF(M10="C",5,IF(M10="RA",0,IF(M10="U",0,IF(M10="UA",0,0))))))))) -> 10 | AD10: =IF(N10="O",10,IF(N10="A+",9,IF(N10="A",8,IF(N10="B+",7,IF(N10="B",6,IF(N10="C",5,IF(N10="RA",0,IF(N10="U",0,IF(N10="UA",0,0))))))))) -> 7 | AG10: =(W10*W$7)+(X10*X$7)+(Y10*Y$7)+(Z10*Z$7)+(AA10*AA$7)+(AB10*AB$7)+(AC10*AC$7)+(AD10*AD$7) -> 199 | AH10: =IF(W10=0,0,W$7)+IF(X10=0,0,X$7)+IF(Y10=0,0,Y$7)+IF(Z10=0,0,Z$7)+IF(AA10=0,0,AA$7)+IF(AB10=0,0,AB$7)+IF(AC10=0,0,AC$7)+IF(AD10=0,0,AD$7) -> 23 | AI10: =IF(AH10=0,0,AG10/AH10) -> 8.6521739 | AJ10: =IF(AH10=23,"P","F") -> P | AK10: =IF(F10>179,1,0) -> 0 | AL10: =IF(F10>159,1,0)-AK10 -> 0 | AM10: =IF(F10>139,1,0)-(AK10+AL10) -> 0 | AN10: =IF(F10>119,1,0)-(AK10+AL10+AM10) -> 0 | AO10: =IF(F10>109,1,0)-(AK10+AL10+AM10+AN10) -> 0 | AP10: =IF(F10>=100,1,0)-(AK10+AL10+AM10+AN10+AO10) -> 0 | AQ10: =IF(F10<100,1,0) -> 1 | AS10: =IF(AK10=0,0,AJ10) -> 0 | AT10: =IF(AL10=0,0,AJ10) -> 0 | AU10: =IF(AM10=0,0,AJ10) -> 0 | AV10: =IF(AN10=0,0,AJ10) -> 0 | AW10: =IF(AO10=0,0,AJ10) -> 0 | AX10: =IF(AP10=0,0,AJ10) -> 0 | AY10: =IF(AQ10=0,0,AJ10) -> P | AZ10: =CONCATENATE(E10,D10) -> HM | BA10: =CONCATENATE(AZ10,V10) -> HMT | BB10: =IF(AZ10="HM",AJ10,"#") -> P | BC10: =IF(AZ10="HF",AJ10,"#") -> # | BD10: =IF(AZ10="DM",AJ10,"#") -> # | BE10: =IF(AZ10="DF",AJ10,"#") -> # | BG10: =IF(AZ10="HM",O10,"#") -> 0 | BH10: =IF(AZ10="HF",O10,"#") -> # | BI10: =IF(AZ10="DM",O10,"#") -> # | BJ10: =IF(AZ10="DF",O10,"#") -> # | BK10: =IF(D10="M",O10,"#") -> 0 | BL10: =IF(D10="F",O10,"#") -> # | BP10: =IF(BA10="HMT",AJ10,"#") -> P | BQ10: =IF(BA10="HFT",AJ10,"#") -> # | BR10: =IF(BA10="DMT",AJ10,"#") -> # | BS10: =IF(BA10="DFT",AJ10,"#") -> # | BT10: =IF(BA10="HMNT",AJ10,"#") -> # | BU10: =IF(BA10="HFNT",AJ10,"#") -> # | BV10: =IF(BA10="DMNT",AJ10,"#") -> # | BW10: =IF(BA10="DFNT",AJ10,"#") -> # | BY10: =IF(BA10="HMT",O10,"#") -> 0 | BZ10: =IF(BA10="HFT",O10,"#") -> # | CA10: =IF(BA10="DMT",O10,"#") -> # | CB10: =IF(BA10="DFT",O10,"#") -> # | CC10: =IF(BA10="HMNT",O10,"#") -> # | CD10: =IF(BA10="HFNT",O10,"#") -> # | CE10: =IF(BA10="DMNT",O10,"#") -> # | CF10: =IF(BA10="DFNT",O10,"#") -> # | CG10: =IF(D10="M",O10,"#") -> 0 | CH10: =IF(D10="F",O10,"#") -> # | CK10: =IF(W10=0,"EEP,"," ") | CL10: =IF(X10=0,"POC,"," ") | CM10: =IF(Y10=0,"DAV,"," ") | CN10: =IF(Z10=0,"EP,"," ") | CO10: =IF(AA10=0,"MAD,"," ") | CP10: =IF(AB10=0,"CCP,"," ") | CQ10: =IF(AC10=0,"UIUX,"," ") | CR10: =IF(AD10=0,"DEV,"," ") | CT10: =O10 -> 0 | CU10: =A10 -> 3 | CV10: =B10 -> 24IT0003 | CW10: =C10 -> ADITHYA A M | CX10: =CONCATENATE(CK10,CL10,CM10,CN10,CO10,CP10,CQ10,CR10,CS10) | CY10: =CT10 -> 0 | DA10: =IF(E10="H",O10,"#") -> 0 | DB10: =IF(E10="D",O10,"#") -> #
A11: 4 | B11: 24IT0004 | C11: ADITHYA AJAY | D11: M | E11: H | G11: O | H11: B | I11: B+ | J11: A+ | K11: A | L11: A | M11: O | N11: B+ | O11: =COUNTIF(G11:N11,"U")+COUNTIF(G11:N11,"UA")+COUNTIF(G11:N11,"WH") -> 0 | Q11: =AH11 -> 23 | R11: 7.76 | V11: T | W11: =IF(G11="O",10,IF(G11="A+",9,IF(G11="A",8,IF(G11="B+",7,IF(G11="B",6,IF(G11="C",5,IF(G11="RA",0,IF(G11="U",0,IF(G11="UA",0,0))))))))) -> 10 | X11: =IF(H11="O",10,IF(H11="A+",9,IF(H11="A",8,IF(H11="B+",7,IF(H11="B",6,IF(H11="C",5,IF(H11="RA",0,IF(H11="U",0,IF(H11="UA",0,0))))))))) -> 6 | Y11: =IF(I11="O",10,IF(I11="A+",9,IF(I11="A",8,IF(I11="B+",7,IF(I11="B",6,IF(I11="C",5,IF(I11="RA",0,IF(I11="U",0,IF(I11="UA",0,0))))))))) -> 7 | Z11: =IF(J11="O",10,IF(J11="A+",9,IF(J11="A",8,IF(J11="B+",7,IF(J11="B",6,IF(J11="C",5,IF(J11="RA",0,IF(J11="U",0,IF(J11="UA",0,0))))))))) -> 9 | AA11: =IF(K11="O",10,IF(K11="A+",9,IF(K11="A",8,IF(K11="B+",7,IF(K11="B",6,IF(K11="C",5,IF(K11="RA",0,IF(K11="U",0,IF(K11="UA",0,0))))))))) -> 8 | AB11: =IF(L11="O",10,IF(L11="A+",9,IF(L11="A",8,IF(L11="B+",7,IF(L11="B",6,IF(L11="C",5,IF(L11="RA",0,IF(L11="U",0,IF(L11="UA",0,0))))))))) -> 8 | AC11: =IF(M11="O",10,IF(M11="A+",9,IF(M11="A",8,IF(M11="B+",7,IF(M11="B",6,IF(M11="C",5,IF(M11="RA",0,IF(M11="U",0,IF(M11="UA",0,0))))))))) -> 10 | AD11: =IF(N11="O",10,IF(N11="A+",9,IF(N11="A",8,IF(N11="B+",7,IF(N11="B",6,IF(N11="C",5,IF(N11="RA",0,IF(N11="U",0,IF(N11="UA",0,0))))))))) -> 7 | AG11: =(W11*W$7)+(X11*X$7)+(Y11*Y$7)+(Z11*Z$7)+(AA11*AA$7)+(AB11*AB$7)+(AC11*AC$7)+(AD11*AD$7) -> 181 | AH11: =IF(W11=0,0,W$7)+IF(X11=0,0,X$7)+IF(Y11=0,0,Y$7)+IF(Z11=0,0,Z$7)+IF(AA11=0,0,AA$7)+IF(AB11=0,0,AB$7)+IF(AC11=0,0,AC$7)+IF(AD11=0,0,AD$7) -> 23 | AI11: =IF(AH11=0,0,AG11/AH11) -> 7.8695652 | AJ11: =IF(AH11=23,"P","F") -> P | AK11: =IF(F11>179,1,0) -> 0 | AL11: =IF(F11>159,1,0)-AK11 -> 0 | AM11: =IF(F11>139,1,0)-(AK11+AL11) -> 0 | AN11: =IF(F11>119,1,0)-(AK11+AL11+AM11) -> 0 | AO11: =IF(F11>109,1,0)-(AK11+AL11+AM11+AN11) -> 0 | AP11: =IF(F11>=100,1,0)-(AK11+AL11+AM11+AN11+AO11) -> 0 | AQ11: =IF(F11<100,1,0) -> 1 | AS11: =IF(AK11=0,0,AJ11) -> 0 | AT11: =IF(AL11=0,0,AJ11) -> 0 | AU11: =IF(AM11=0,0,AJ11) -> 0 | AV11: =IF(AN11=0,0,AJ11) -> 0 | AW11: =IF(AO11=0,0,AJ11) -> 0 | AX11: =IF(AP11=0,0,AJ11) -> 0 | AY11: =IF(AQ11=0,0,AJ11) -> P | AZ11: =CONCATENATE(E11,D11) -> HM | BA11: =CONCATENATE(AZ11,V11) -> HMT | BB11: =IF(AZ11="HM",AJ11,"#") -> P | BC11: =IF(AZ11="HF",AJ11,"#") -> # | BD11: =IF(AZ11="DM",AJ11,"#") -> # | BE11: =IF(AZ11="DF",AJ11,"#") -> # | BG11: =IF(AZ11="HM",O11,"#") -> 0 | BH11: =IF(AZ11="HF",O11,"#") -> # | BI11: =IF(AZ11="DM",O11,"#") -> # | BJ11: =IF(AZ11="DF",O11,"#") -> # | BK11: =IF(D11="M",O11,"#") -> 0 | BL11: =IF(D11="F",O11,"#") -> # | BP11: =IF(BA11="HMT",AJ11,"#") -> P | BQ11: =IF(BA11="HFT",AJ11,"#") -> # | BR11: =IF(BA11="DMT",AJ11,"#") -> # | BS11: =IF(BA11="DFT",AJ11,"#") -> # | BT11: =IF(BA11="HMNT",AJ11,"#") -> # | BU11: =IF(BA11="HFNT",AJ11,"#") -> # | BV11: =IF(BA11="DMNT",AJ11,"#") -> # | BW11: =IF(BA11="DFNT",AJ11,"#") -> # | BY11: =IF(BA11="HMT",O11,"#") -> 0 | BZ11: =IF(BA11="HFT",O11,"#") -> # | CA11: =IF(BA11="DMT",O11,"#") -> # | CB11: =IF(BA11="DFT",O11,"#") -> # | CC11: =IF(BA11="HMNT",O11,"#") -> # | CD11: =IF(BA11="HFNT",O11,"#") -> # | CE11: =IF(BA11="DMNT",O11,"#") -> # | CF11: =IF(BA11="DFNT",O11,"#") -> # | CG11: =IF(D11="M",O11,"#") -> 0 | CH11: =IF(D11="F",O11,"#") -> # | CK11: =IF(W11=0,"EEP,"," ") | CL11: =IF(X11=0,"POC,"," ") | CM11: =IF(Y11=0,"DAV,"," ") | CN11: =IF(Z11=0,"EP,"," ") | CO11: =IF(AA11=0,"MAD,"," ") | CP11: =IF(AB11=0,"CCP,"," ") | CQ11: =IF(AC11=0,"UIUX,"," ") | CR11: =IF(AD11=0,"DEV,"," ") | CT11: =O11 -> 0 | CU11: =A11 -> 4 | CV11: =B11 -> 24IT0004 | CW11: =C11 -> ADITHYA AJAY | CX11: =CONCATENATE(CK11,CL11,CM11,CN11,CO11,CP11,CQ11,CR11,CS11) | CY11: =CT11 -> 0 | DA11: =IF(E11="H",O11,"#") -> 0 | DB11: =IF(E11="D",O11,"#") -> #
A12: 5 | B12: 24IT0005 | C12: AISHVARRYA A | D12: F | E12: D | G12: O | H12: B | I12: B+ | J12: A+ | K12: A | L12: B+ | M12: O | N12: C | O12: =COUNTIF(G12:N12,"U")+COUNTIF(G12:N12,"UA")+COUNTIF(G12:N12,"WH") -> 0 | Q12: =AH12 -> 23 | R12: 7.28 | V12: T | W12: =IF(G12="O",10,IF(G12="A+",9,IF(G12="A",8,IF(G12="B+",7,IF(G12="B",6,IF(G12="C",5,IF(G12="RA",0,IF(G12="U",0,IF(G12="UA",0,0))))))))) -> 10 | X12: =IF(H12="O",10,IF(H12="A+",9,IF(H12="A",8,IF(H12="B+",7,IF(H12="B",6,IF(H12="C",5,IF(H12="RA",0,IF(H12="U",0,IF(H12="UA",0,0))))))))) -> 6 | Y12: =IF(I12="O",10,IF(I12="A+",9,IF(I12="A",8,IF(I12="B+",7,IF(I12="B",6,IF(I12="C",5,IF(I12="RA",0,IF(I12="U",0,IF(I12="UA",0,0))))))))) -> 7 | Z12: =IF(J12="O",10,IF(J12="A+",9,IF(J12="A",8,IF(J12="B+",7,IF(J12="B",6,IF(J12="C",5,IF(J12="RA",0,IF(J12="U",0,IF(J12="UA",0,0))))))))) -> 9 | AA12: =IF(K12="O",10,IF(K12="A+",9,IF(K12="A",8,IF(K12="B+",7,IF(K12="B",6,IF(K12="C",5,IF(K12="RA",0,IF(K12="U",0,IF(K12="UA",0,0))))))))) -> 8 | AB12: =IF(L12="O",10,IF(L12="A+",9,IF(L12="A",8,IF(L12="B+",7,IF(L12="B",6,IF(L12="C",5,IF(L12="RA",0,IF(L12="U",0,IF(L12="UA",0,0))))))))) -> 7 | AC12: =IF(M12="O",10,IF(M12="A+",9,IF(M12="A",8,IF(M12="B+",7,IF(M12="B",6,IF(M12="C",5,IF(M12="RA",0,IF(M12="U",0,IF(M12="UA",0,0))))))))) -> 10 | AD12: =IF(N12="O",10,IF(N12="A+",9,IF(N12="A",8,IF(N12="B+",7,IF(N12="B",6,IF(N12="C",5,IF(N12="RA",0,IF(N12="U",0,IF(N12="UA",0,0))))))))) -> 5 | AG12: =(W12*W$7)+(X12*X$7)+(Y12*Y$7)+(Z12*Z$7)+(AA12*AA$7)+(AB12*AB$7)+(AC12*AC$7)+(AD12*AD$7) -> 174 | AH12: =IF(W12=0,0,W$7)+IF(X12=0,0,X$7)+IF(Y12=0,0,Y$7)+IF(Z12=0,0,Z$7)+IF(AA12=0,0,AA$7)+IF(AB12=0,0,AB$7)+IF(AC12=0,0,AC$7)+IF(AD12=0,0,AD$7) -> 23 | AI12: =IF(AH12=0,0,AG12/AH12) -> 7.5652174 | AJ12: =IF(AH12=23,"P","F") -> P | AK12: =IF(F12>179,1,0) -> 0 | AL12: =IF(F12>159,1,0)-AK12 -> 0 | AM12: =IF(F12>139,1,0)-(AK12+AL12) -> 0 | AN12: =IF(F12>119,1,0)-(AK12+AL12+AM12) -> 0 | AO12: =IF(F12>109,1,0)-(AK12+AL12+AM12+AN12) -> 0 | AP12: =IF(F12>=100,1,0)-(AK12+AL12+AM12+AN12+AO12) -> 0 | AQ12: =IF(F12<100,1,0) -> 1 | AS12: =IF(AK12=0,0,AJ12) -> 0 | AT12: =IF(AL12=0,0,AJ12) -> 0 | AU12: =IF(AM12=0,0,AJ12) -> 0 | AV12: =IF(AN12=0,0,AJ12) -> 0 | AW12: =IF(AO12=0,0,AJ12) -> 0 | AX12: =IF(AP12=0,0,AJ12) -> 0 | AY12: =IF(AQ12=0,0,AJ12) -> P | AZ12: =CONCATENATE(E12,D12) -> DF | BA12: =CONCATENATE(AZ12,V12) -> DFT | BB12: =IF(AZ12="HM",AJ12,"#") -> # | BC12: =IF(AZ12="HF",AJ12,"#") -> # | BD12: =IF(AZ12="DM",AJ12,"#") -> # | BE12: =IF(AZ12="DF",AJ12,"#") -> P | BG12: =IF(AZ12="HM",O12,"#") -> # | BH12: =IF(AZ12="HF",O12,"#") -> # | BI12: =IF(AZ12="DM",O12,"#") -> # | BJ12: =IF(AZ12="DF",O12,"#") -> 0 | BK12: =IF(D12="M",O12,"#") -> # | BL12: =IF(D12="F",O12,"#") -> 0 | BP12: =IF(BA12="HMT",AJ12,"#") -> # | BQ12: =IF(BA12="HFT",AJ12,"#") -> # | BR12: =IF(BA12="DMT",AJ12,"#") -> # | BS12: =IF(BA12="DFT",AJ12,"#") -> P | BT12: =IF(BA12="HMNT",AJ12,"#") -> # | BU12: =IF(BA12="HFNT",AJ12,"#") -> # | BV12: =IF(BA12="DMNT",AJ12,"#") -> # | BW12: =IF(BA12="DFNT",AJ12,"#") -> # | BY12: =IF(BA12="HMT",O12,"#") -> # | BZ12: =IF(BA12="HFT",O12,"#") -> # | CA12: =IF(BA12="DMT",O12,"#") -> # | CB12: =IF(BA12="DFT",O12,"#") -> 0 | CC12: =IF(BA12="HMNT",O12,"#") -> # | CD12: =IF(BA12="HFNT",O12,"#") -> # | CE12: =IF(BA12="DMNT",O12,"#") -> # | CF12: =IF(BA12="DFNT",O12,"#") -> # | CG12: =IF(D12="M",O12,"#") -> # | CH12: =IF(D12="F",O12,"#") -> 0 | CK12: =IF(W12=0,"EEP,"," ") | CL12: =IF(X12=0,"POC,"," ") | CM12: =IF(Y12=0,"DAV,"," ") | CN12: =IF(Z12=0,"EP,"," ") | CO12: =IF(AA12=0,"MAD,"," ") | CP12: =IF(AB12=0,"CCP,"," ") | CQ12: =IF(AC12=0,"UIUX,"," ") | CR12: =IF(AD12=0,"DEV,"," ") | CT12: =O12 -> 0 | CU12: =A12 -> 5 | CV12: =B12 -> 24IT0005 | CW12: =C12 -> AISHVARRYA A | CX12: =CONCATENATE(CK12,CL12,CM12,CN12,CO12,CP12,CQ12,CR12,CS12) | CY12: =CT12 -> 0 | DA12: =IF(E12="H",O12,"#") -> # | DB12: =IF(E12="D",O12,"#") -> 0
A13: 6 | B13: 24IT0006 | C13: AISHWARYA S | D13: F | E13: D | G13: O | H13: A | I13: O | J13: A+ | K13: O | L13: A | M13: O | N13: B+ | O13: =COUNTIF(G13:N13,"U")+COUNTIF(G13:N13,"UA")+COUNTIF(G13:N13,"WH") -> 0 | Q13: =AH13 -> 23 | R13: 8.8 | V13: T | W13: =IF(G13="O",10,IF(G13="A+",9,IF(G13="A",8,IF(G13="B+",7,IF(G13="B",6,IF(G13="C",5,IF(G13="RA",0,IF(G13="U",0,IF(G13="UA",0,0))))))))) -> 10 | X13: =IF(H13="O",10,IF(H13="A+",9,IF(H13="A",8,IF(H13="B+",7,IF(H13="B",6,IF(H13="C",5,IF(H13="RA",0,IF(H13="U",0,IF(H13="UA",0,0))))))))) -> 8 | Y13: =IF(I13="O",10,IF(I13="A+",9,IF(I13="A",8,IF(I13="B+",7,IF(I13="B",6,IF(I13="C",5,IF(I13="RA",0,IF(I13="U",0,IF(I13="UA",0,0))))))))) -> 10 | Z13: =IF(J13="O",10,IF(J13="A+",9,IF(J13="A",8,IF(J13="B+",7,IF(J13="B",6,IF(J13="C",5,IF(J13="RA",0,IF(J13="U",0,IF(J13="UA",0,0))))))))) -> 9 | AA13: =IF(K13="O",10,IF(K13="A+",9,IF(K13="A",8,IF(K13="B+",7,IF(K13="B",6,IF(K13="C",5,IF(K13="RA",0,IF(K13="U",0,IF(K13="UA",0,0))))))))) -> 10 | AB13: =IF(L13="O",10,IF(L13="A+",9,IF(L13="A",8,IF(L13="B+",7,IF(L13="B",6,IF(L13="C",5,IF(L13="RA",0,IF(L13="U",0,IF(L13="UA",0,0))))))))) -> 8 | AC13: =IF(M13="O",10,IF(M13="A+",9,IF(M13="A",8,IF(M13="B+",7,IF(M13="B",6,IF(M13="C",5,IF(M13="RA",0,IF(M13="U",0,IF(M13="UA",0,0))))))))) -> 10 | AD13: =IF(N13="O",10,IF(N13="A+",9,IF(N13="A",8,IF(N13="B+",7,IF(N13="B",6,IF(N13="C",5,IF(N13="RA",0,IF(N13="U",0,IF(N13="UA",0,0))))))))) -> 7 | AG13: =(W13*W$7)+(X13*X$7)+(Y13*Y$7)+(Z13*Z$7)+(AA13*AA$7)+(AB13*AB$7)+(AC13*AC$7)+(AD13*AD$7) -> 207 | AH13: =IF(W13=0,0,W$7)+IF(X13=0,0,X$7)+IF(Y13=0,0,Y$7)+IF(Z13=0,0,Z$7)+IF(AA13=0,0,AA$7)+IF(AB13=0,0,AB$7)+IF(AC13=0,0,AC$7)+IF(AD13=0,0,AD$7) -> 23 | AI13: =IF(AH13=0,0,AG13/AH13) -> 9 | AJ13: =IF(AH13=23,"P","F") -> P | AK13: =IF(F13>179,1,0) -> 0 | AL13: =IF(F13>159,1,0)-AK13 -> 0 | AM13: =IF(F13>139,1,0)-(AK13+AL13) -> 0 | AN13: =IF(F13>119,1,0)-(AK13+AL13+AM13) -> 0 | AO13: =IF(F13>109,1,0)-(AK13+AL13+AM13+AN13) -> 0 | AP13: =IF(F13>=100,1,0)-(AK13+AL13+AM13+AN13+AO13) -> 0 | AQ13: =IF(F13<100,1,0) -> 1 | AS13: =IF(AK13=0,0,AJ13) -> 0 | AT13: =IF(AL13=0,0,AJ13) -> 0 | AU13: =IF(AM13=0,0,AJ13) -> 0 | AV13: =IF(AN13=0,0,AJ13) -> 0 | AW13: =IF(AO13=0,0,AJ13) -> 0 | AX13: =IF(AP13=0,0,AJ13) -> 0 | AY13: =IF(AQ13=0,0,AJ13) -> P | AZ13: =CONCATENATE(E13,D13) -> DF | BA13: =CONCATENATE(AZ13,V13) -> DFT | BB13: =IF(AZ13="HM",AJ13,"#") -> # | BC13: =IF(AZ13="HF",AJ13,"#") -> # | BD13: =IF(AZ13="DM",AJ13,"#") -> # | BE13: =IF(AZ13="DF",AJ13,"#") -> P | BG13: =IF(AZ13="HM",O13,"#") -> # | BH13: =IF(AZ13="HF",O13,"#") -> # | BI13: =IF(AZ13="DM",O13,"#") -> # | BJ13: =IF(AZ13="DF",O13,"#") -> 0 | BK13: =IF(D13="M",O13,"#") -> # | BL13: =IF(D13="F",O13,"#") -> 0 | BP13: =IF(BA13="HMT",AJ13,"#") -> # | BQ13: =IF(BA13="HFT",AJ13,"#") -> # | BR13: =IF(BA13="DMT",AJ13,"#") -> # | BS13: =IF(BA13="DFT",AJ13,"#") -> P | BT13: =IF(BA13="HMNT",AJ13,"#") -> # | BU13: =IF(BA13="HFNT",AJ13,"#") -> # | BV13: =IF(BA13="DMNT",AJ13,"#") -> # | BW13: =IF(BA13="DFNT",AJ13,"#") -> # | BY13: =IF(BA13="HMT",O13,"#") -> # | BZ13: =IF(BA13="HFT",O13,"#") -> # | CA13: =IF(BA13="DMT",O13,"#") -> # | CB13: =IF(BA13="DFT",O13,"#") -> 0 | CC13: =IF(BA13="HMNT",O13,"#") -> # | CD13: =IF(BA13="HFNT",O13,"#") -> # | CE13: =IF(BA13="DMNT",O13,"#") -> # | CF13: =IF(BA13="DFNT",O13,"#") -> # | CG13: =IF(D13="M",O13,"#") -> # | CH13: =IF(D13="F",O13,"#") -> 0 | CK13: =IF(W13=0,"EEP,"," ") | CL13: =IF(X13=0,"POC,"," ") | CM13: =IF(Y13=0,"DAV,"," ") | CN13: =IF(Z13=0,"EP,"," ") | CO13: =IF(AA13=0,"MAD,"," ") | CP13: =IF(AB13=0,"CCP,"," ") | CQ13: =IF(AC13=0,"UIUX,"," ") | CR13: =IF(AD13=0,"DEV,"," ") | CT13: =O13 -> 0 | CU13: =A13 -> 6 | CV13: =B13 -> 24IT0006 | CW13: =C13 -> AISHWARYA S | CX13: =CONCATENATE(CK13,CL13,CM13,CN13,CO13,CP13,CQ13,CR13,CS13) | CY13: =CT13 -> 0 | DA13: =IF(E13="H",O13,"#") -> # | DB13: =IF(E13="D",O13,"#") -> 0
A14: 7 | B14: 24IT0007 | C14: AJAY J | D14: M | E14: H | G14: O | H14: B | I14: B+ | J14: RA | K14: A | L14: B+ | M14: O | N14: RA | O14: =COUNTIF(G14:N14,"U")+COUNTIF(G14:N14,"UA")+COUNTIF(G14:N14,"WH") -> 0 | Q14: =AH14 -> 16 | R14: 7.41 | V14: T | W14: =IF(G14="O",10,IF(G14="A+",9,IF(G14="A",8,IF(G14="B+",7,IF(G14="B",6,IF(G14="C",5,IF(G14="RA",0,IF(G14="U",0,IF(G14="UA",0,0))))))))) -> 10 | X14: =IF(H14="O",10,IF(H14="A+",9,IF(H14="A",8,IF(H14="B+",7,IF(H14="B",6,IF(H14="C",5,IF(H14="RA",0,IF(H14="U",0,IF(H14="UA",0,0))))))))) -> 6 | Y14: =IF(I14="O",10,IF(I14="A+",9,IF(I14="A",8,IF(I14="B+",7,IF(I14="B",6,IF(I14="C",5,IF(I14="RA",0,IF(I14="U",0,IF(I14="UA",0,0))))))))) -> 7 | Z14: =IF(J14="O",10,IF(J14="A+",9,IF(J14="A",8,IF(J14="B+",7,IF(J14="B",6,IF(J14="C",5,IF(J14="RA",0,IF(J14="U",0,IF(J14="UA",0,0))))))))) -> 0 | AA14: =IF(K14="O",10,IF(K14="A+",9,IF(K14="A",8,IF(K14="B+",7,IF(K14="B",6,IF(K14="C",5,IF(K14="RA",0,IF(K14="U",0,IF(K14="UA",0,0))))))))) -> 8 | AB14: =IF(L14="O",10,IF(L14="A+",9,IF(L14="A",8,IF(L14="B+",7,IF(L14="B",6,IF(L14="C",5,IF(L14="RA",0,IF(L14="U",0,IF(L14="UA",0,0))))))))) -> 7 | AC14: =IF(M14="O",10,IF(M14="A+",9,IF(M14="A",8,IF(M14="B+",7,IF(M14="B",6,IF(M14="C",5,IF(M14="RA",0,IF(M14="U",0,IF(M14="UA",0,0))))))))) -> 10 | AD14: =IF(N14="O",10,IF(N14="A+",9,IF(N14="A",8,IF(N14="B+",7,IF(N14="B",6,IF(N14="C",5,IF(N14="RA",0,IF(N14="U",0,IF(N14="UA",0,0))))))))) -> 0 | AG14: =(W14*W$7)+(X14*X$7)+(Y14*Y$7)+(Z14*Z$7)+(AA14*AA$7)+(AB14*AB$7)+(AC14*AC$7)+(AD14*AD$7) -> 123 | AH14: =IF(W14=0,0,W$7)+IF(X14=0,0,X$7)+IF(Y14=0,0,Y$7)+IF(Z14=0,0,Z$7)+IF(AA14=0,0,AA$7)+IF(AB14=0,0,AB$7)+IF(AC14=0,0,AC$7)+IF(AD14=0,0,AD$7) -> 16 | AI14: =IF(AH14=0,0,AG14/AH14) -> 7.6875 | AJ14: =IF(AH14=23,"P","F") -> F | AK14: =IF(F14>179,1,0) -> 0 | AL14: =IF(F14>159,1,0)-AK14 -> 0 | AM14: =IF(F14>139,1,0)-(AK14+AL14) -> 0 | AN14: =IF(F14>119,1,0)-(AK14+AL14+AM14) -> 0 | AO14: =IF(F14>109,1,0)-(AK14+AL14+AM14+AN14) -> 0 | AP14: =IF(F14>=100,1,0)-(AK14+AL14+AM14+AN14+AO14) -> 0 | AQ14: =IF(F14<100,1,0) -> 1 | AS14: =IF(AK14=0,0,AJ14) -> 0 | AT14: =IF(AL14=0,0,AJ14) -> 0 | AU14: =IF(AM14=0,0,AJ14) -> 0 | AV14: =IF(AN14=0,0,AJ14) -> 0 | AW14: =IF(AO14=0,0,AJ14) -> 0 | AX14: =IF(AP14=0,0,AJ14) -> 0 | AY14: =IF(AQ14=0,0,AJ14) -> F | AZ14: =CONCATENATE(E14,D14) -> HM | BA14: =CONCATENATE(AZ14,V14) -> HMT | BB14: =IF(AZ14="HM",AJ14,"#") -> F | BC14: =IF(AZ14="HF",AJ14,"#") -> # | BD14: =IF(AZ14="DM",AJ14,"#") -> # | BE14: =IF(AZ14="DF",AJ14,"#") -> # | BG14: =IF(AZ14="HM",O14,"#") -> 0 | BH14: =IF(AZ14="HF",O14,"#") -> # | BI14: =IF(AZ14="DM",O14,"#") -> # | BJ14: =IF(AZ14="DF",O14,"#") -> # | BK14: =IF(D14="M",O14,"#") -> 0 | BL14: =IF(D14="F",O14,"#") -> # | BP14: =IF(BA14="HMT",AJ14,"#") -> F | BQ14: =IF(BA14="HFT",AJ14,"#") -> # | BR14: =IF(BA14="DMT",AJ14,"#") -> # | BS14: =IF(BA14="DFT",AJ14,"#") -> # | BT14: =IF(BA14="HMNT",AJ14,"#") -> # | BU14: =IF(BA14="HFNT",AJ14,"#") -> # | BV14: =IF(BA14="DMNT",AJ14,"#") -> # | BW14: =IF(BA14="DFNT",AJ14,"#") -> # | BY14: =IF(BA14="HMT",O14,"#") -> 0 | BZ14: =IF(BA14="HFT",O14,"#") -> # | CA14: =IF(BA14="DMT",O14,"#") -> # | CB14: =IF(BA14="DFT",O14,"#") -> # | CC14: =IF(BA14="HMNT",O14,"#") -> # | CD14: =IF(BA14="HFNT",O14,"#") -> # | CE14: =IF(BA14="DMNT",O14,"#") -> # | CF14: =IF(BA14="DFNT",O14,"#") -> # | CG14: =IF(D14="M",O14,"#") -> 0 | CH14: =IF(D14="F",O14,"#") -> # | CK14: =IF(W14=0,"EEP,"," ") | CL14: =IF(X14=0,"POC,"," ") | CM14: =IF(Y14=0,"DAV,"," ") | CN14: =IF(Z14=0,"EP,"," ") -> EP, | CO14: =IF(AA14=0,"MAD,"," ") | CP14: =IF(AB14=0,"CCP,"," ") | CQ14: =IF(AC14=0,"UIUX,"," ") | CR14: =IF(AD14=0,"DEV,"," ") -> DEV, | CT14: =O14 -> 0 | CU14: =A14 -> 7 | CV14: =B14 -> 24IT0007 | CW14: =C14 -> AJAY J | CX14: =CONCATENATE(CK14,CL14,CM14,CN14,CO14,CP14,CQ14,CR14,CS14) -> EP, DEV, | CY14: =CT14 -> 0 | DA14: =IF(E14="H",O14,"#") -> 0 | DB14: =IF(E14="D",O14,"#") -> #
A15: 8 | B15: 24IT0008 | C15: AKSHAYA I | D15: F | E15: H | G15: O | H15: A | I15: A+ | J15: A+ | K15: O | L15: A | M15: O | N15: B+ | O15: =COUNTIF(G15:N15,"U")+COUNTIF(G15:N15,"UA")+COUNTIF(G15:N15,"WH") -> 0 | Q15: =AH15 -> 23 | R15: 8.64 | V15: T | W15: =IF(G15="O",10,IF(G15="A+",9,IF(G15="A",8,IF(G15="B+",7,IF(G15="B",6,IF(G15="C",5,IF(G15="RA",0,IF(G15="U",0,IF(G15="UA",0,0))))))))) -> 10 | X15: =IF(H15="O",10,IF(H15="A+",9,IF(H15="A",8,IF(H15="B+",7,IF(H15="B",6,IF(H15="C",5,IF(H15="RA",0,IF(H15="U",0,IF(H15="UA",0,0))))))))) -> 8 | Y15: =IF(I15="O",10,IF(I15="A+",9,IF(I15="A",8,IF(I15="B+",7,IF(I15="B",6,IF(I15="C",5,IF(I15="RA",0,IF(I15="U",0,IF(I15="UA",0,0))))))))) -> 9 | Z15: =IF(J15="O",10,IF(J15="A+",9,IF(J15="A",8,IF(J15="B+",7,IF(J15="B",6,IF(J15="C",5,IF(J15="RA",0,IF(J15="U",0,IF(J15="UA",0,0))))))))) -> 9 | AA15: =IF(K15="O",10,IF(K15="A+",9,IF(K15="A",8,IF(K15="B+",7,IF(K15="B",6,IF(K15="C",5,IF(K15="RA",0,IF(K15="U",0,IF(K15="UA",0,0))))))))) -> 10 | AB15: =IF(L15="O",10,IF(L15="A+",9,IF(L15="A",8,IF(L15="B+",7,IF(L15="B",6,IF(L15="C",5,IF(L15="RA",0,IF(L15="U",0,IF(L15="UA",0,0))))))))) -> 8 | AC15: =IF(M15="O",10,IF(M15="A+",9,IF(M15="A",8,IF(M15="B+",7,IF(M15="B",6,IF(M15="C",5,IF(M15="RA",0,IF(M15="U",0,IF(M15="UA",0,0))))))))) -> 10 | AD15: =IF(N15="O",10,IF(N15="A+",9,IF(N15="A",8,IF(N15="B+",7,IF(N15="B",6,IF(N15="C",5,IF(N15="RA",0,IF(N15="U",0,IF(N15="UA",0,0))))))))) -> 7 | AG15: =(W15*W$7)+(X15*X$7)+(Y15*Y$7)+(Z15*Z$7)+(AA15*AA$7)+(AB15*AB$7)+(AC15*AC$7)+(AD15*AD$7) -> 203 | AH15: =IF(W15=0,0,W$7)+IF(X15=0,0,X$7)+IF(Y15=0,0,Y$7)+IF(Z15=0,0,Z$7)+IF(AA15=0,0,AA$7)+IF(AB15=0,0,AB$7)+IF(AC15=0,0,AC$7)+IF(AD15=0,0,AD$7) -> 23 | AI15: =IF(AH15=0,0,AG15/AH15) -> 8.826087 | AJ15: =IF(AH15=23,"P","F") -> P | AK15: =IF(F15>179,1,0) -> 0 | AL15: =IF(F15>159,1,0)-AK15 -> 0 | AM15: =IF(F15>139,1,0)-(AK15+AL15) -> 0 | AN15: =IF(F15>119,1,0)-(AK15+AL15+AM15) -> 0 | AO15: =IF(F15>109,1,0)-(AK15+AL15+AM15+AN15) -> 0 | AP15: =IF(F15>=100,1,0)-(AK15+AL15+AM15+AN15+AO15) -> 0 | AQ15: =IF(F15<100,1,0) -> 1 | AS15: =IF(AK15=0,0,AJ15) -> 0 | AT15: =IF(AL15=0,0,AJ15) -> 0 | AU15: =IF(AM15=0,0,AJ15) -> 0 | AV15: =IF(AN15=0,0,AJ15) -> 0 | AW15: =IF(AO15=0,0,AJ15) -> 0 | AX15: =IF(AP15=0,0,AJ15) -> 0 | AY15: =IF(AQ15=0,0,AJ15) -> P | AZ15: =CONCATENATE(E15,D15) -> HF | BA15: =CONCATENATE(AZ15,V15) -> HFT | BB15: =IF(AZ15="HM",AJ15,"#") -> # | BC15: =IF(AZ15="HF",AJ15,"#") -> P | BD15: =IF(AZ15="DM",AJ15,"#") -> # | BE15: =IF(AZ15="DF",AJ15,"#") -> # | BG15: =IF(AZ15="HM",O15,"#") -> # | BH15: =IF(AZ15="HF",O15,"#") -> 0 | BI15: =IF(AZ15="DM",O15,"#") -> # | BJ15: =IF(AZ15="DF",O15,"#") -> # | BK15: =IF(D15="M",O15,"#") -> # | BL15: =IF(D15="F",O15,"#") -> 0 | BP15: =IF(BA15="HMT",AJ15,"#") -> # | BQ15: =IF(BA15="HFT",AJ15,"#") -> P | BR15: =IF(BA15="DMT",AJ15,"#") -> # | BS15: =IF(BA15="DFT",AJ15,"#") -> # | BT15: =IF(BA15="HMNT",AJ15,"#") -> # | BU15: =IF(BA15="HFNT",AJ15,"#") -> # | BV15: =IF(BA15="DMNT",AJ15,"#") -> # | BW15: =IF(BA15="DFNT",AJ15,"#") -> # | BY15: =IF(BA15="HMT",O15,"#") -> # | BZ15: =IF(BA15="HFT",O15,"#") -> 0 | CA15: =IF(BA15="DMT",O15,"#") -> # | CB15: =IF(BA15="DFT",O15,"#") -> # | CC15: =IF(BA15="HMNT",O15,"#") -> # | CD15: =IF(BA15="HFNT",O15,"#") -> # | CE15: =IF(BA15="DMNT",O15,"#") -> # | CF15: =IF(BA15="DFNT",O15,"#") -> # | CG15: =IF(D15="M",O15,"#") -> # | CH15: =IF(D15="F",O15,"#") -> 0 | CK15: =IF(W15=0,"EEP,"," ") | CL15: =IF(X15=0,"POC,"," ") | CM15: =IF(Y15=0,"DAV,"," ") | CN15: =IF(Z15=0,"EP,"," ") | CO15: =IF(AA15=0,"MAD,"," ") | CP15: =IF(AB15=0,"CCP,"," ") | CQ15: =IF(AC15=0,"UIUX,"," ") | CR15: =IF(AD15=0,"DEV,"," ") | CT15: =O15 -> 0 | CU15: =A15 -> 8 | CV15: =B15 -> 24IT0008 | CW15: =C15 -> AKSHAYA I | CX15: =CONCATENATE(CK15,CL15,CM15,CN15,CO15,CP15,CQ15,CR15,CS15) | CY15: =CT15 -> 0 | DA15: =IF(E15="H",O15,"#") -> 0 | DB15: =IF(E15="D",O15,"#") -> #
A16: 9 | B16: 24IT0009 | C16: AKSHAYA T | D16: F | E16: D | G16: O | H16: A | I16: A+ | J16: A+ | K16: O | L16: A+ | M16: O | N16: B+ | O16: =COUNTIF(G16:N16,"U")+COUNTIF(G16:N16,"UA")+COUNTIF(G16:N16,"WH") -> 0 | Q16: =AH16 -> 23 | R16: 8.8 | V16: T | W16: =IF(G16="O",10,IF(G16="A+",9,IF(G16="A",8,IF(G16="B+",7,IF(G16="B",6,IF(G16="C",5,IF(G16="RA",0,IF(G16="U",0,IF(G16="UA",0,0))))))))) -> 10 | X16: =IF(H16="O",10,IF(H16="A+",9,IF(H16="A",8,IF(H16="B+",7,IF(H16="B",6,IF(H16="C",5,IF(H16="RA",0,IF(H16="U",0,IF(H16="UA",0,0))))))))) -> 8 | Y16: =IF(I16="O",10,IF(I16="A+",9,IF(I16="A",8,IF(I16="B+",7,IF(I16="B",6,IF(I16="C",5,IF(I16="RA",0,IF(I16="U",0,IF(I16="UA",0,0))))))))) -> 9 | Z16: =IF(J16="O",10,IF(J16="A+",9,IF(J16="A",8,IF(J16="B+",7,IF(J16="B",6,IF(J16="C",5,IF(J16="RA",0,IF(J16="U",0,IF(J16="UA",0,0))))))))) -> 9 | AA16: =IF(K16="O",10,IF(K16="A+",9,IF(K16="A",8,IF(K16="B+",7,IF(K16="B",6,IF(K16="C",5,IF(K16="RA",0,IF(K16="U",0,IF(K16="UA",0,0))))))))) -> 10 | AB16: =IF(L16="O",10,IF(L16="A+",9,IF(L16="A",8,IF(L16="B+",7,IF(L16="B",6,IF(L16="C",5,IF(L16="RA",0,IF(L16="U",0,IF(L16="UA",0,0))))))))) -> 9 | AC16: =IF(M16="O",10,IF(M16="A+",9,IF(M16="A",8,IF(M16="B+",7,IF(M16="B",6,IF(M16="C",5,IF(M16="RA",0,IF(M16="U",0,IF(M16="UA",0,0))))))))) -> 10 | AD16: =IF(N16="O",10,IF(N16="A+",9,IF(N16="A",8,IF(N16="B+",7,IF(N16="B",6,IF(N16="C",5,IF(N16="RA",0,IF(N16="U",0,IF(N16="UA",0,0))))))))) -> 7 | AG16: =(W16*W$7)+(X16*X$7)+(Y16*Y$7)+(Z16*Z$7)+(AA16*AA$7)+(AB16*AB$7)+(AC16*AC$7)+(AD16*AD$7) -> 204 | AH16: =IF(W16=0,0,W$7)+IF(X16=0,0,X$7)+IF(Y16=0,0,Y$7)+IF(Z16=0,0,Z$7)+IF(AA16=0,0,AA$7)+IF(AB16=0,0,AB$7)+IF(AC16=0,0,AC$7)+IF(AD16=0,0,AD$7) -> 23 | AI16: =IF(AH16=0,0,AG16/AH16) -> 8.8695652 | AJ16: =IF(AH16=23,"P","F") -> P | AK16: =IF(F16>179,1,0) -> 0 | AL16: =IF(F16>159,1,0)-AK16 -> 0 | AM16: =IF(F16>139,1,0)-(AK16+AL16) -> 0 | AN16: =IF(F16>119,1,0)-(AK16+AL16+AM16) -> 0 | AO16: =IF(F16>109,1,0)-(AK16+AL16+AM16+AN16) -> 0 | AP16: =IF(F16>=100,1,0)-(AK16+AL16+AM16+AN16+AO16) -> 0 | AQ16: =IF(F16<100,1,0) -> 1 | AS16: =IF(AK16=0,0,AJ16) -> 0 | AT16: =IF(AL16=0,0,AJ16) -> 0 | AU16: =IF(AM16=0,0,AJ16) -> 0 | AV16: =IF(AN16=0,0,AJ16) -> 0 | AW16: =IF(AO16=0,0,AJ16) -> 0 | AX16: =IF(AP16=0,0,AJ16) -> 0 | AY16: =IF(AQ16=0,0,AJ16) -> P | AZ16: =CONCATENATE(E16,D16) -> DF | BA16: =CONCATENATE(AZ16,V16) -> DFT | BB16: =IF(AZ16="HM",AJ16,"#") -> # | BC16: =IF(AZ16="HF",AJ16,"#") -> # | BD16: =IF(AZ16="DM",AJ16,"#") -> # | BE16: =IF(AZ16="DF",AJ16,"#") -> P | BG16: =IF(AZ16="HM",O16,"#") -> # | BH16: =IF(AZ16="HF",O16,"#") -> # | BI16: =IF(AZ16="DM",O16,"#") -> # | BJ16: =IF(AZ16="DF",O16,"#") -> 0 | BK16: =IF(D16="M",O16,"#") -> # | BL16: =IF(D16="F",O16,"#") -> 0 | BP16: =IF(BA16="HMT",AJ16,"#") -> # | BQ16: =IF(BA16="HFT",AJ16,"#") -> # | BR16: =IF(BA16="DMT",AJ16,"#") -> # | BS16: =IF(BA16="DFT",AJ16,"#") -> P | BT16: =IF(BA16="HMNT",AJ16,"#") -> # | BU16: =IF(BA16="HFNT",AJ16,"#") -> # | BV16: =IF(BA16="DMNT",AJ16,"#") -> # | BW16: =IF(BA16="DFNT",AJ16,"#") -> # | BY16: =IF(BA16="HMT",O16,"#") -> # | BZ16: =IF(BA16="HFT",O16,"#") -> # | CA16: =IF(BA16="DMT",O16,"#") -> # | CB16: =IF(BA16="DFT",O16,"#") -> 0 | CC16: =IF(BA16="HMNT",O16,"#") -> # | CD16: =IF(BA16="HFNT",O16,"#") -> # | CE16: =IF(BA16="DMNT",O16,"#") -> # | CF16: =IF(BA16="DFNT",O16,"#") -> # | CG16: =IF(D16="M",O16,"#") -> # | CH16: =IF(D16="F",O16,"#") -> 0 | CK16: =IF(W16=0,"EEP,"," ") | CL16: =IF(X16=0,"POC,"," ") | CM16: =IF(Y16=0,"DAV,"," ") | CN16: =IF(Z16=0,"EP,"," ") | CO16: =IF(AA16=0,"MAD,"," ") | CP16: =IF(AB16=0,"CCP,"," ") | CQ16: =IF(AC16=0,"UIUX,"," ") | CR16: =IF(AD16=0,"DEV,"," ") | CT16: =O16 -> 0 | CU16: =A16 -> 9 | CV16: =B16 -> 24IT0009 | CW16: =C16 -> AKSHAYA T | CX16: =CONCATENATE(CK16,CL16,CM16,CN16,CO16,CP16,CQ16,CR16,CS16) | CY16: =CT16 -> 0 | DA16: =IF(E16="H",O16,"#") -> # | DB16: =IF(E16="D",O16,"#") -> 0
A17: 10 | B17: 24IT0010 | C17: AMIZHTHINI I | D17: F | E17: H | G17: O | H17: A | I17: B+ | J17: A+ | K17: O | L17: A | M17: O | N17: B+ | O17: =COUNTIF(G17:N17,"U")+COUNTIF(G17:N17,"UA")+COUNTIF(G17:N17,"WH") -> 0 | Q17: =AH17 -> 23 | R17: 8.32 | V17: T | W17: =IF(G17="O",10,IF(G17="A+",9,IF(G17="A",8,IF(G17="B+",7,IF(G17="B",6,IF(G17="C",5,IF(G17="RA",0,IF(G17="U",0,IF(G17="UA",0,0))))))))) -> 10 | X17: =IF(H17="O",10,IF(H17="A+",9,IF(H17="A",8,IF(H17="B+",7,IF(H17="B",6,IF(H17="C",5,IF(H17="RA",0,IF(H17="U",0,IF(H17="UA",0,0))))))))) -> 8 | Y17: =IF(I17="O",10,IF(I17="A+",9,IF(I17="A",8,IF(I17="B+",7,IF(I17="B",6,IF(I17="C",5,IF(I17="RA",0,IF(I17="U",0,IF(I17="UA",0,0))))))))) -> 7 | Z17: =IF(J17="O",10,IF(J17="A+",9,IF(J17="A",8,IF(J17="B+",7,IF(J17="B",6,IF(J17="C",5,IF(J17="RA",0,IF(J17="U",0,IF(J17="UA",0,0))))))))) -> 9 | AA17: =IF(K17="O",10,IF(K17="A+",9,IF(K17="A",8,IF(K17="B+",7,IF(K17="B",6,IF(K17="C",5,IF(K17="RA",0,IF(K17="U",0,IF(K17="UA",0,0))))))))) -> 10 | AB17: =IF(L17="O",10,IF(L17="A+",9,IF(L17="A",8,IF(L17="B+",7,IF(L17="B",6,IF(L17="C",5,IF(L17="RA",0,IF(L17="U",0,IF(L17="UA",0,0))))))))) -> 8 | AC17: =IF(M17="O",10,IF(M17="A+",9,IF(M17="A",8,IF(M17="B+",7,IF(M17="B",6,IF(M17="C",5,IF(M17="RA",0,IF(M17="U",0,IF(M17="UA",0,0))))))))) -> 10 | AD17: =IF(N17="O",10,IF(N17="A+",9,IF(N17="A",8,IF(N17="B+",7,IF(N17="B",6,IF(N17="C",5,IF(N17="RA",0,IF(N17="U",0,IF(N17="UA",0,0))))))))) -> 7 | AG17: =(W17*W$7)+(X17*X$7)+(Y17*Y$7)+(Z17*Z$7)+(AA17*AA$7)+(AB17*AB$7)+(AC17*AC$7)+(AD17*AD$7) -> 195 | AH17: =IF(W17=0,0,W$7)+IF(X17=0,0,X$7)+IF(Y17=0,0,Y$7)+IF(Z17=0,0,Z$7)+IF(AA17=0,0,AA$7)+IF(AB17=0,0,AB$7)+IF(AC17=0,0,AC$7)+IF(AD17=0,0,AD$7) -> 23 | AI17: =IF(AH17=0,0,AG17/AH17) -> 8.4782609 | AJ17: =IF(AH17=23,"P","F") -> P | AK17: =IF(F17>179,1,0) -> 0 | AL17: =IF(F17>159,1,0)-AK17 -> 0 | AM17: =IF(F17>139,1,0)-(AK17+AL17) -> 0 | AN17: =IF(F17>119,1,0)-(AK17+AL17+AM17) -> 0 | AO17: =IF(F17>109,1,0)-(AK17+AL17+AM17+AN17) -> 0 | AP17: =IF(F17>=100,1,0)-(AK17+AL17+AM17+AN17+AO17) -> 0 | AQ17: =IF(F17<100,1,0) -> 1 | AS17: =IF(AK17=0,0,AJ17) -> 0 | AT17: =IF(AL17=0,0,AJ17) -> 0 | AU17: =IF(AM17=0,0,AJ17) -> 0 | AV17: =IF(AN17=0,0,AJ17) -> 0 | AW17: =IF(AO17=0,0,AJ17) -> 0 | AX17: =IF(AP17=0,0,AJ17) -> 0 | AY17: =IF(AQ17=0,0,AJ17) -> P | AZ17: =CONCATENATE(E17,D17) -> HF | BA17: =CONCATENATE(AZ17,V17) -> HFT | BB17: =IF(AZ17="HM",AJ17,"#") -> # | BC17: =IF(AZ17="HF",AJ17,"#") -> P | BD17: =IF(AZ17="DM",AJ17,"#") -> # | BE17: =IF(AZ17="DF",AJ17,"#") -> # | BG17: =IF(AZ17="HM",O17,"#") -> # | BH17: =IF(AZ17="HF",O17,"#") -> 0 | BI17: =IF(AZ17="DM",O17,"#") -> # | BJ17: =IF(AZ17="DF",O17,"#") -> # | BK17: =IF(D17="M",O17,"#") -> # | BL17: =IF(D17="F",O17,"#") -> 0 | BP17: =IF(BA17="HMT",AJ17,"#") -> # | BQ17: =IF(BA17="HFT",AJ17,"#") -> P | BR17: =IF(BA17="DMT",AJ17,"#") -> # | BS17: =IF(BA17="DFT",AJ17,"#") -> # | BT17: =IF(BA17="HMNT",AJ17,"#") -> # | BU17: =IF(BA17="HFNT",AJ17,"#") -> # | BV17: =IF(BA17="DMNT",AJ17,"#") -> # | BW17: =IF(BA17="DFNT",AJ17,"#") -> # | BY17: =IF(BA17="HMT",O17,"#") -> # | BZ17: =IF(BA17="HFT",O17,"#") -> 0 | CA17: =IF(BA17="DMT",O17,"#") -> # | CB17: =IF(BA17="DFT",O17,"#") -> # | CC17: =IF(BA17="HMNT",O17,"#") -> # | CD17: =IF(BA17="HFNT",O17,"#") -> # | CE17: =IF(BA17="DMNT",O17,"#") -> # | CF17: =IF(BA17="DFNT",O17,"#") -> # | CG17: =IF(D17="M",O17,"#") -> # | CH17: =IF(D17="F",O17,"#") -> 0 | CK17: =IF(W17=0,"EEP,"," ") | CL17: =IF(X17=0,"POC,"," ") | CM17: =IF(Y17=0,"DAV,"," ") | CN17: =IF(Z17=0,"EP,"," ") | CO17: =IF(AA17=0,"MAD,"," ") | CP17: =IF(AB17=0,"CCP,"," ") | CQ17: =IF(AC17=0,"UIUX,"," ") | CR17: =IF(AD17=0,"DEV,"," ") | CT17: =O17 -> 0 | CU17: =A17 -> 10 | CV17: =B17 -> 24IT0010 | CW17: =C17 -> AMIZHTHINI I | CX17: =CONCATENATE(CK17,CL17,CM17,CN17,CO17,CP17,CQ17,CR17,CS17) | CY17: =CT17 -> 0 | DA17: =IF(E17="H",O17,"#") -> 0 | DB17: =IF(E17="D",O17,"#") -> #
A18: 11 | B18: 24IT0011 | C18: ANGELIN FELINA A | D18: F | E18: H | G18: O | H18: A+ | I18: O | J18: A+ | K18: O | L18: O | M18: O | N18: B+ | O18: =COUNTIF(G18:N18,"U")+COUNTIF(G18:N18,"UA")+COUNTIF(G18:N18,"WH") -> 0 | Q18: =AH18 -> 23 | R18: 9.24 | V18: T | W18: =IF(G18="O",10,IF(G18="A+",9,IF(G18="A",8,IF(G18="B+",7,IF(G18="B",6,IF(G18="C",5,IF(G18="RA",0,IF(G18="U",0,IF(G18="UA",0,0))))))))) -> 10 | X18: =IF(H18="O",10,IF(H18="A+",9,IF(H18="A",8,IF(H18="B+",7,IF(H18="B",6,IF(H18="C",5,IF(H18="RA",0,IF(H18="U",0,IF(H18="UA",0,0))))))))) -> 9 | Y18: =IF(I18="O",10,IF(I18="A+",9,IF(I18="A",8,IF(I18="B+",7,IF(I18="B",6,IF(I18="C",5,IF(I18="RA",0,IF(I18="U",0,IF(I18="UA",0,0))))))))) -> 10 | Z18: =IF(J18="O",10,IF(J18="A+",9,IF(J18="A",8,IF(J18="B+",7,IF(J18="B",6,IF(J18="C",5,IF(J18="RA",0,IF(J18="U",0,IF(J18="UA",0,0))))))))) -> 9 | AA18: =IF(K18="O",10,IF(K18="A+",9,IF(K18="A",8,IF(K18="B+",7,IF(K18="B",6,IF(K18="C",5,IF(K18="RA",0,IF(K18="U",0,IF(K18="UA",0,0))))))))) -> 10 | AB18: =IF(L18="O",10,IF(L18="A+",9,IF(L18="A",8,IF(L18="B+",7,IF(L18="B",6,IF(L18="C",5,IF(L18="RA",0,IF(L18="U",0,IF(L18="UA",0,0))))))))) -> 10 | AC18: =IF(M18="O",10,IF(M18="A+",9,IF(M18="A",8,IF(M18="B+",7,IF(M18="B",6,IF(M18="C",5,IF(M18="RA",0,IF(M18="U",0,IF(M18="UA",0,0))))))))) -> 10 | AD18: =IF(N18="O",10,IF(N18="A+",9,IF(N18="A",8,IF(N18="B+",7,IF(N18="B",6,IF(N18="C",5,IF(N18="RA",0,IF(N18="U",0,IF(N18="UA",0,0))))))))) -> 7 | AG18: =(W18*W$7)+(X18*X$7)+(Y18*Y$7)+(Z18*Z$7)+(AA18*AA$7)+(AB18*AB$7)+(AC18*AC$7)+(AD18*AD$7) -> 213 | AH18: =IF(W18=0,0,W$7)+IF(X18=0,0,X$7)+IF(Y18=0,0,Y$7)+IF(Z18=0,0,Z$7)+IF(AA18=0,0,AA$7)+IF(AB18=0,0,AB$7)+IF(AC18=0,0,AC$7)+IF(AD18=0,0,AD$7) -> 23 | AI18: =IF(AH18=0,0,AG18/AH18) -> 9.2608696 | AJ18: =IF(AH18=23,"P","F") -> P | AK18: =IF(F18>179,1,0) -> 0 | AL18: =IF(F18>159,1,0)-AK18 -> 0 | AM18: =IF(F18>139,1,0)-(AK18+AL18) -> 0 | AN18: =IF(F18>119,1,0)-(AK18+AL18+AM18) -> 0 | AO18: =IF(F18>109,1,0)-(AK18+AL18+AM18+AN18) -> 0 | AP18: =IF(F18>=100,1,0)-(AK18+AL18+AM18+AN18+AO18) -> 0 | AQ18: =IF(F18<100,1,0) -> 1 | AS18: =IF(AK18=0,0,AJ18) -> 0 | AT18: =IF(AL18=0,0,AJ18) -> 0 | AU18: =IF(AM18=0,0,AJ18) -> 0 | AV18: =IF(AN18=0,0,AJ18) -> 0 | AW18: =IF(AO18=0,0,AJ18) -> 0 | AX18: =IF(AP18=0,0,AJ18) -> 0 | AY18: =IF(AQ18=0,0,AJ18) -> P | AZ18: =CONCATENATE(E18,D18) -> HF | BA18: =CONCATENATE(AZ18,V18) -> HFT | BB18: =IF(AZ18="HM",AJ18,"#") -> # | BC18: =IF(AZ18="HF",AJ18,"#") -> P | BD18: =IF(AZ18="DM",AJ18,"#") -> # | BE18: =IF(AZ18="DF",AJ18,"#") -> # | BG18: =IF(AZ18="HM",O18,"#") -> # | BH18: =IF(AZ18="HF",O18,"#") -> 0 | BI18: =IF(AZ18="DM",O18,"#") -> # | BJ18: =IF(AZ18="DF",O18,"#") -> # | BK18: =IF(D18="M",O18,"#") -> # | BL18: =IF(D18="F",O18,"#") -> 0 | BP18: =IF(BA18="HMT",AJ18,"#") -> # | BQ18: =IF(BA18="HFT",AJ18,"#") -> P | BR18: =IF(BA18="DMT",AJ18,"#") -> # | BS18: =IF(BA18="DFT",AJ18,"#") -> # | BT18: =IF(BA18="HMNT",AJ18,"#") -> # | BU18: =IF(BA18="HFNT",AJ18,"#") -> # | BV18: =IF(BA18="DMNT",AJ18,"#") -> # | BW18: =IF(BA18="DFNT",AJ18,"#") -> # | BY18: =IF(BA18="HMT",O18,"#") -> # | BZ18: =IF(BA18="HFT",O18,"#") -> 0 | CA18: =IF(BA18="DMT",O18,"#") -> # | CB18: =IF(BA18="DFT",O18,"#") -> # | CC18: =IF(BA18="HMNT",O18,"#") -> # | CD18: =IF(BA18="HFNT",O18,"#") -> # | CE18: =IF(BA18="DMNT",O18,"#") -> # | CF18: =IF(BA18="DFNT",O18,"#") -> # | CG18: =IF(D18="M",O18,"#") -> # | CH18: =IF(D18="F",O18,"#") -> 0 | CK18: =IF(W18=0,"EEP,"," ") | CL18: =IF(X18=0,"POC,"," ") | CM18: =IF(Y18=0,"DAV,"," ") | CN18: =IF(Z18=0,"EP,"," ") | CO18: =IF(AA18=0,"MAD,"," ") | CP18: =IF(AB18=0,"CCP,"," ") | CQ18: =IF(AC18=0,"UIUX,"," ") | CR18: =IF(AD18=0,"DEV,"," ") | CT18: =O18 -> 0 | CU18: =A18 -> 11 | CV18: =B18 -> 24IT0011 | CW18: =C18 -> ANGELIN FELINA A | CX18: =CONCATENATE(CK18,CL18,CM18,CN18,CO18,CP18,CQ18,CR18,CS18) | CY18: =CT18 -> 0 | DA18: =IF(E18="H",O18,"#") -> 0 | DB18: =IF(E18="D",O18,"#") -> #
A19: 12 | B19: 24IT0012 | C19: AQSAR AKKIM T A | D19: M | E19: D | G19: O | H19: A | I19: A | J19: A+ | K19: A | L19: A | M19: O | N19: B+ | O19: =COUNTIF(G19:N19,"U")+COUNTIF(G19:N19,"UA")+COUNTIF(G19:N19,"WH") -> 0 | Q19: =AH19 -> 23 | R19: 8.16 | V19: T | W19: =IF(G19="O",10,IF(G19="A+",9,IF(G19="A",8,IF(G19="B+",7,IF(G19="B",6,IF(G19="C",5,IF(G19="RA",0,IF(G19="U",0,IF(G19="UA",0,0))))))))) -> 10 | X19: =IF(H19="O",10,IF(H19="A+",9,IF(H19="A",8,IF(H19="B+",7,IF(H19="B",6,IF(H19="C",5,IF(H19="RA",0,IF(H19="U",0,IF(H19="UA",0,0))))))))) -> 8 | Y19: =IF(I19="O",10,IF(I19="A+",9,IF(I19="A",8,IF(I19="B+",7,IF(I19="B",6,IF(I19="C",5,IF(I19="RA",0,IF(I19="U",0,IF(I19="UA",0,0))))))))) -> 8 | Z19: =IF(J19="O",10,IF(J19="A+",9,IF(J19="A",8,IF(J19="B+",7,IF(J19="B",6,IF(J19="C",5,IF(J19="RA",0,IF(J19="U",0,IF(J19="UA",0,0))))))))) -> 9 | AA19: =IF(K19="O",10,IF(K19="A+",9,IF(K19="A",8,IF(K19="B+",7,IF(K19="B",6,IF(K19="C",5,IF(K19="RA",0,IF(K19="U",0,IF(K19="UA",0,0))))))))) -> 8 | AB19: =IF(L19="O",10,IF(L19="A+",9,IF(L19="A",8,IF(L19="B+",7,IF(L19="B",6,IF(L19="C",5,IF(L19="RA",0,IF(L19="U",0,IF(L19="UA",0,0))))))))) -> 8 | AC19: =IF(M19="O",10,IF(M19="A+",9,IF(M19="A",8,IF(M19="B+",7,IF(M19="B",6,IF(M19="C",5,IF(M19="RA",0,IF(M19="U",0,IF(M19="UA",0,0))))))))) -> 10 | AD19: =IF(N19="O",10,IF(N19="A+",9,IF(N19="A",8,IF(N19="B+",7,IF(N19="B",6,IF(N19="C",5,IF(N19="RA",0,IF(N19="U",0,IF(N19="UA",0,0))))))))) -> 7 | AG19: =(W19*W$7)+(X19*X$7)+(Y19*Y$7)+(Z19*Z$7)+(AA19*AA$7)+(AB19*AB$7)+(AC19*AC$7)+(AD19*AD$7) -> 193 | AH19: =IF(W19=0,0,W$7)+IF(X19=0,0,X$7)+IF(Y19=0,0,Y$7)+IF(Z19=0,0,Z$7)+IF(AA19=0,0,AA$7)+IF(AB19=0,0,AB$7)+IF(AC19=0,0,AC$7)+IF(AD19=0,0,AD$7) -> 23 | AI19: =IF(AH19=0,0,AG19/AH19) -> 8.3913043 | AJ19: =IF(AH19=23,"P","F") -> P | AK19: =IF(F19>179,1,0) -> 0 | AL19: =IF(F19>159,1,0)-AK19 -> 0 | AM19: =IF(F19>139,1,0)-(AK19+AL19) -> 0 | AN19: =IF(F19>119,1,0)-(AK19+AL19+AM19) -> 0 | AO19: =IF(F19>109,1,0)-(AK19+AL19+AM19+AN19) -> 0 | AP19: =IF(F19>=100,1,0)-(AK19+AL19+AM19+AN19+AO19) -> 0 | AQ19: =IF(F19<100,1,0) -> 1 | AS19: =IF(AK19=0,0,AJ19) -> 0 | AT19: =IF(AL19=0,0,AJ19) -> 0 | AU19: =IF(AM19=0,0,AJ19) -> 0 | AV19: =IF(AN19=0,0,AJ19) -> 0 | AW19: =IF(AO19=0,0,AJ19) -> 0 | AX19: =IF(AP19=0,0,AJ19) -> 0 | AY19: =IF(AQ19=0,0,AJ19) -> P | AZ19: =CONCATENATE(E19,D19) -> DM | BA19: =CONCATENATE(AZ19,V19) -> DMT | BB19: =IF(AZ19="HM",AJ19,"#") -> # | BC19: =IF(AZ19="HF",AJ19,"#") -> # | BD19: =IF(AZ19="DM",AJ19,"#") -> P | BE19: =IF(AZ19="DF",AJ19,"#") -> # | BG19: =IF(AZ19="HM",O19,"#") -> # | BH19: =IF(AZ19="HF",O19,"#") -> # | BI19: =IF(AZ19="DM",O19,"#") -> 0 | BJ19: =IF(AZ19="DF",O19,"#") -> # | BK19: =IF(D19="M",O19,"#") -> 0 | BL19: =IF(D19="F",O19,"#") -> # | BP19: =IF(BA19="HMT",AJ19,"#") -> # | BQ19: =IF(BA19="HFT",AJ19,"#") -> # | BR19: =IF(BA19="DMT",AJ19,"#") -> P | BS19: =IF(BA19="DFT",AJ19,"#") -> # | BT19: =IF(BA19="HMNT",AJ19,"#") -> # | BU19: =IF(BA19="HFNT",AJ19,"#") -> # | BV19: =IF(BA19="DMNT",AJ19,"#") -> # | BW19: =IF(BA19="DFNT",AJ19,"#") -> # | BY19: =IF(BA19="HMT",O19,"#") -> # | BZ19: =IF(BA19="HFT",O19,"#") -> # | CA19: =IF(BA19="DMT",O19,"#") -> 0 | CB19: =IF(BA19="DFT",O19,"#") -> # | CC19: =IF(BA19="HMNT",O19,"#") -> # | CD19: =IF(BA19="HFNT",O19,"#") -> # | CE19: =IF(BA19="DMNT",O19,"#") -> # | CF19: =IF(BA19="DFNT",O19,"#") -> # | CG19: =IF(D19="M",O19,"#") -> 0 | CH19: =IF(D19="F",O19,"#") -> # | CK19: =IF(W19=0,"EEP,"," ") | CL19: =IF(X19=0,"POC,"," ") | CM19: =IF(Y19=0,"DAV,"," ") | CN19: =IF(Z19=0,"EP,"," ") | CO19: =IF(AA19=0,"MAD,"," ") | CP19: =IF(AB19=0,"CCP,"," ") | CQ19: =IF(AC19=0,"UIUX,"," ") | CR19: =IF(AD19=0,"DEV,"," ") | CT19: =O19 -> 0 | CU19: =A19 -> 12 | CV19: =B19 -> 24IT0012 | CW19: =C19 -> AQSAR AKKIM T A | CX19: =CONCATENATE(CK19,CL19,CM19,CN19,CO19,CP19,CQ19,CR19,CS19) | CY19: =CT19 -> 0 | DA19: =IF(E19="H",O19,"#") -> # | DB19: =IF(E19="D",O19,"#") -> 0
... A39: 32 | B39: 24IT0032 | C39: DINESH S | D39: M | E39: D | G39: O | H39: A | I39: A | J39: A+ | K39: B+ | L39: B+ | M39: O | N39: B+ | O39: =COUNTIF(G39:N39,"U")+COUNTIF(G39:N39,"UA")+COUNTIF(G39:N39,"WH") -> 0 | Q39: =AH39 -> 23 | R39: 7.84 | V39: T | W39: =IF(G39="O",10,IF(G39="A+",9,IF(G39="A",8,IF(G39="B+",7,IF(G39="B",6,IF(G39="C",5,IF(G39="RA",0,IF(G39="U",0,IF(G39="UA",0,0))))))))) -> 10 | X39: =IF(H39="O",10,IF(H39="A+",9,IF(H39="A",8,IF(H39="B+",7,IF(H39="B",6,IF(H39="C",5,IF(H39="RA",0,IF(H39="U",0,IF(H39="UA",0,0))))))))) -> 8 | Y39: =IF(I39="O",10,IF(I39="A+",9,IF(I39="A",8,IF(I39="B+",7,IF(I39="B",6,IF(I39="C",5,IF(I39="RA",0,IF(I39="U",0,IF(I39="UA",0,0))))))))) -> 8 | Z39: =IF(J39="O",10,IF(J39="A+",9,IF(J39="A",8,IF(J39="B+",7,IF(J39="B",6,IF(J39="C",5,IF(J39="RA",0,IF(J39="U",0,IF(J39="UA",0,0))))))))) -> 9 | AA39: =IF(K39="O",10,IF(K39="A+",9,IF(K39="A",8,IF(K39="B+",7,IF(K39="B",6,IF(K39="C",5,IF(K39="RA",0,IF(K39="U",0,IF(K39="UA",0,0))))))))) -> 7 | AB39: =IF(L39="O",10,IF(L39="A+",9,IF(L39="A",8,IF(L39="B+",7,IF(L39="B",6,IF(L39="C",5,IF(L39="RA",0,IF(L39="U",0,IF(L39="UA",0,0))))))))) -> 7 | AC39: =IF(M39="O",10,IF(M39="A+",9,IF(M39="A",8,IF(M39="B+",7,IF(M39="B",6,IF(M39="C",5,IF(M39="RA",0,IF(M39="U",0,IF(M39="UA",0,0))))))))) -> 10 | AD39: =IF(N39="O",10,IF(N39="A+",9,IF(N39="A",8,IF(N39="B+",7,IF(N39="B",6,IF(N39="C",5,IF(N39="RA",0,IF(N39="U",0,IF(N39="UA",0,0))))))))) -> 7 | AG39: =(W39*W$7)+(X39*X$7)+(Y39*Y$7)+(Z39*Z$7)+(AA39*AA$7)+(AB39*AB$7)+(AC39*AC$7)+(AD39*AD$7) -> 189 | AH39: =IF(W39=0,0,W$7)+IF(X39=0,0,X$7)+IF(Y39=0,0,Y$7)+IF(Z39=0,0,Z$7)+IF(AA39=0,0,AA$7)+IF(AB39=0,0,AB$7)+IF(AC39=0,0,AC$7)+IF(AD39=0,0,AD$7) -> 23 | AI39: =IF(AH39=0,0,AG39/AH39) -> 8.2173913 | AJ39: =IF(AH39=23,"P","F") -> P | AK39: =IF(F39>179,1,0) -> 0 | AL39: =IF(F39>159,1,0)-AK39 -> 0 | AM39: =IF(F39>139,1,0)-(AK39+AL39) -> 0 | AN39: =IF(F39>119,1,0)-(AK39+AL39+AM39) -> 0 | AO39: =IF(F39>109,1,0)-(AK39+AL39+AM39+AN39) -> 0 | AP39: =IF(F39>=100,1,0)-(AK39+AL39+AM39+AN39+AO39) -> 0 | AQ39: =IF(F39<100,1,0) -> 1 | AS39: =IF(AK39=0,0,AJ39) -> 0 | AT39: =IF(AL39=0,0,AJ39) -> 0 | AU39: =IF(AM39=0,0,AJ39) -> 0 | AV39: =IF(AN39=0,0,AJ39) -> 0 | AW39: =IF(AO39=0,0,AJ39) -> 0 | AX39: =IF(AP39=0,0,AJ39) -> 0 | AY39: =IF(AQ39=0,0,AJ39) -> P | AZ39: =CONCATENATE(E39,D39) -> DM | BA39: =CONCATENATE(AZ39,V39) -> DMT | BB39: =IF(AZ39="HM",AJ39,"#") -> # | BC39: =IF(AZ39="HF",AJ39,"#") -> # | BD39: =IF(AZ39="DM",AJ39,"#") -> P | BE39: =IF(AZ39="DF",AJ39,"#") -> # | BG39: =IF(AZ39="HM",O39,"#") -> # | BH39: =IF(AZ39="HF",O39,"#") -> # | BI39: =IF(AZ39="DM",O39,"#") -> 0 | BJ39: =IF(AZ39="DF",O39,"#") -> # | BK39: =IF(D39="M",O39,"#") -> 0 | BL39: =IF(D39="F",O39,"#") -> # | BP39: =IF(BA39="HMT",AJ39,"#") -> # | BQ39: =IF(BA39="HFT",AJ39,"#") -> # | BR39: =IF(BA39="DMT",AJ39,"#") -> P | BS39: =IF(BA39="DFT",AJ39,"#") -> # | BT39: =IF(BA39="HMNT",AJ39,"#") -> # | BU39: =IF(BA39="HFNT",AJ39,"#") -> # | BV39: =IF(BA39="DMNT",AJ39,"#") -> # | BW39: =IF(BA39="DFNT",AJ39,"#") -> # | BY39: =IF(BA39="HMT",O39,"#") -> # | BZ39: =IF(BA39="HFT",O39,"#") -> # | CA39: =IF(BA39="DMT",O39,"#") -> 0 | CB39: =IF(BA39="DFT",O39,"#") -> # | CC39: =IF(BA39="HMNT",O39,"#") -> # | CD39: =IF(BA39="HFNT",O39,"#") -> # | CE39: =IF(BA39="DMNT",O39,"#") -> # | CF39: =IF(BA39="DFNT",O39,"#") -> # | CG39: =IF(D39="M",O39,"#") -> 0 | CH39: =IF(D39="F",O39,"#") -> # | CK39: =IF(W39=0,"EEP,"," ") | CL39: =IF(X39=0,"POC,"," ") | CM39: =IF(Y39=0,"DAV,"," ") | CN39: =IF(Z39=0,"EP,"," ") | CO39: =IF(AA39=0,"MAD,"," ") | CP39: =IF(AB39=0,"CCP,"," ") | CQ39: =IF(AC39=0,"UIUX,"," ") | CR39: =IF(AD39=0,"DEV,"," ") | CT39: =O39 -> 0 | CU39: =A39 -> 32 | CV39: =B39 -> 24IT0032 | CW39: =C39 -> DINESH S | CX39: =CONCATENATE(CK39,CL39,CM39,CN39,CO39,CP39,CQ39,CR39,CS39) | CY39: =CT39 -> 0 | DA39: =IF(E39="H",O39,"#") -> # | DB39: =IF(E39="D",O39,"#") -> 0
A40: 33 | B40: 24IT0033 | C40: DIVYASRI V S | E40: D | G40: O | H40: A | I40: A+ | J40: A+ | K40: B+ | L40: A | M40: O | N40: B+ | O40: =COUNTIF(G40:N40,"U")+COUNTIF(G40:N40,"UA")+COUNTIF(G40:N40,"WH") -> 0 | Q40: =AH40 -> 23 | R40: 8.16 | V40: T | W40: =IF(G40="O",10,IF(G40="A+",9,IF(G40="A",8,IF(G40="B+",7,IF(G40="B",6,IF(G40="C",5,IF(G40="RA",0,IF(G40="U",0,IF(G40="UA",0,0))))))))) -> 10 | X40: =IF(H40="O",10,IF(H40="A+",9,IF(H40="A",8,IF(H40="B+",7,IF(H40="B",6,IF(H40="C",5,IF(H40="RA",0,IF(H40="U",0,IF(H40="UA",0,0))))))))) -> 8 | Y40: =IF(I40="O",10,IF(I40="A+",9,IF(I40="A",8,IF(I40="B+",7,IF(I40="B",6,IF(I40="C",5,IF(I40="RA",0,IF(I40="U",0,IF(I40="UA",0,0))))))))) -> 9 | Z40: =IF(J40="O",10,IF(J40="A+",9,IF(J40="A",8,IF(J40="B+",7,IF(J40="B",6,IF(J40="C",5,IF(J40="RA",0,IF(J40="U",0,IF(J40="UA",0,0))))))))) -> 9 | AA40: =IF(K40="O",10,IF(K40="A+",9,IF(K40="A",8,IF(K40="B+",7,IF(K40="B",6,IF(K40="C",5,IF(K40="RA",0,IF(K40="U",0,IF(K40="UA",0,0))))))))) -> 7 | AB40: =IF(L40="O",10,IF(L40="A+",9,IF(L40="A",8,IF(L40="B+",7,IF(L40="B",6,IF(L40="C",5,IF(L40="RA",0,IF(L40="U",0,IF(L40="UA",0,0))))))))) -> 8 | AC40: =IF(M40="O",10,IF(M40="A+",9,IF(M40="A",8,IF(M40="B+",7,IF(M40="B",6,IF(M40="C",5,IF(M40="RA",0,IF(M40="U",0,IF(M40="UA",0,0))))))))) -> 10 | AD40: =IF(N40="O",10,IF(N40="A+",9,IF(N40="A",8,IF(N40="B+",7,IF(N40="B",6,IF(N40="C",5,IF(N40="RA",0,IF(N40="U",0,IF(N40="UA",0,0))))))))) -> 7 | AG40: =(W40*W$7)+(X40*X$7)+(Y40*Y$7)+(Z40*Z$7)+(AA40*AA$7)+(AB40*AB$7)+(AC40*AC$7)+(AD40*AD$7) -> 194 | AH40: =IF(W40=0,0,W$7)+IF(X40=0,0,X$7)+IF(Y40=0,0,Y$7)+IF(Z40=0,0,Z$7)+IF(AA40=0,0,AA$7)+IF(AB40=0,0,AB$7)+IF(AC40=0,0,AC$7)+IF(AD40=0,0,AD$7) -> 23 | AI40: =IF(AH40=0,0,AG40/AH40) -> 8.4347826 | AJ40: =IF(AH40=23,"P","F") -> P | AK40: =IF(F40>179,1,0) -> 0 | AL40: =IF(F40>159,1,0)-AK40 -> 0 | AM40: =IF(F40>139,1,0)-(AK40+AL40) -> 0 | AN40: =IF(F40>119,1,0)-(AK40+AL40+AM40) -> 0 | AO40: =IF(F40>109,1,0)-(AK40+AL40+AM40+AN40) -> 0 | AP40: =IF(F40>=100,1,0)-(AK40+AL40+AM40+AN40+AO40) -> 0 | AQ40: =IF(F40<100,1,0) -> 1 | AS40: =IF(AK40=0,0,AJ40) -> 0 | AT40: =IF(AL40=0,0,AJ40) -> 0 | AU40: =IF(AM40=0,0,AJ40) -> 0 | AV40: =IF(AN40=0,0,AJ40) -> 0 | AW40: =IF(AO40=0,0,AJ40) -> 0 | AX40: =IF(AP40=0,0,AJ40) -> 0 | AY40: =IF(AQ40=0,0,AJ40) -> P | AZ40: =CONCATENATE(E40,D40) -> D | BA40: =CONCATENATE(AZ40,V40) -> DT | BB40: =IF(AZ40="HM",AJ40,"#") -> # | BC40: =IF(AZ40="HF",AJ40,"#") -> # | BD40: =IF(AZ40="DM",AJ40,"#") -> # | BE40: =IF(AZ40="DF",AJ40,"#") -> # | BG40: =IF(AZ40="HM",O40,"#") -> # | BH40: =IF(AZ40="HF",O40,"#") -> # | BI40: =IF(AZ40="DM",O40,"#") -> # | BJ40: =IF(AZ40="DF",O40,"#") -> # | BK40: =IF(D40="M",O40,"#") -> # | BL40: =IF(D40="F",O40,"#") -> # | BP40: =IF(BA40="HMT",AJ40,"#") -> # | BQ40: =IF(BA40="HFT",AJ40,"#") -> # | BR40: =IF(BA40="DMT",AJ40,"#") -> # | BS40: =IF(BA40="DFT",AJ40,"#") -> # | BT40: =IF(BA40="HMNT",AJ40,"#") -> # | BU40: =IF(BA40="HFNT",AJ40,"#") -> # | BV40: =IF(BA40="DMNT",AJ40,"#") -> # | BW40: =IF(BA40="DFNT",AJ40,"#") -> # | BY40: =IF(BA40="HMT",O40,"#") -> # | BZ40: =IF(BA40="HFT",O40,"#") -> # | CA40: =IF(BA40="DMT",O40,"#") -> # | CB40: =IF(BA40="DFT",O40,"#") -> # | CC40: =IF(BA40="HMNT",O40,"#") -> # | CD40: =IF(BA40="HFNT",O40,"#") -> # | CE40: =IF(BA40="DMNT",O40,"#") -> # | CF40: =IF(BA40="DFNT",O40,"#") -> # | CG40: =IF(D40="M",O40,"#") -> # | CH40: =IF(D40="F",O40,"#") -> # | CK40: =IF(W40=0,"EEP,"," ") | CL40: =IF(X40=0,"POC,"," ") | CM40: =IF(Y40=0,"DAV,"," ") | CN40: =IF(Z40=0,"EP,"," ") | CO40: =IF(AA40=0,"MAD,"," ") | CP40: =IF(AB40=0,"CCP,"," ") | CQ40: =IF(AC40=0,"UIUX,"," ") | CR40: =IF(AD40=0,"DEV,"," ") | CT40: =O40 -> 0 | CU40: =A40 -> 33 | CV40: =B40 -> 24IT0033 | CW40: =C40 -> DIVYASRI V S | CX40: =CONCATENATE(CK40,CL40,CM40,CN40,CO40,CP40,CQ40,CR40,CS40) | CY40: =CT40 -> 0 | DA40: =IF(E40="H",O40,"#") -> # | DB40: =IF(E40="D",O40,"#") -> 0
A41: 34 | B41: 24IT0034 | C41: E NITHYAPRABHA | E41: D | G41: O | H41: A | I41: A+ | J41: A+ | K41: A+ | L41: A | M41: O | N41: B+ | O41: =COUNTIF(G41:N41,"U")+COUNTIF(G41:N41,"UA")+COUNTIF(G41:N41,"WH") -> 0 | Q41: =AH41 -> 23 | R41: 8.48 | V41: T | W41: =IF(G41="O",10,IF(G41="A+",9,IF(G41="A",8,IF(G41="B+",7,IF(G41="B",6,IF(G41="C",5,IF(G41="RA",0,IF(G41="U",0,IF(G41="UA",0,0))))))))) -> 10 | X41: =IF(H41="O",10,IF(H41="A+",9,IF(H41="A",8,IF(H41="B+",7,IF(H41="B",6,IF(H41="C",5,IF(H41="RA",0,IF(H41="U",0,IF(H41="UA",0,0))))))))) -> 8 | Y41: =IF(I41="O",10,IF(I41="A+",9,IF(I41="A",8,IF(I41="B+",7,IF(I41="B",6,IF(I41="C",5,IF(I41="RA",0,IF(I41="U",0,IF(I41="UA",0,0))))))))) -> 9 | Z41: =IF(J41="O",10,IF(J41="A+",9,IF(J41="A",8,IF(J41="B+",7,IF(J41="B",6,IF(J41="C",5,IF(J41="RA",0,IF(J41="U",0,IF(J41="UA",0,0))))))))) -> 9 | AA41: =IF(K41="O",10,IF(K41="A+",9,IF(K41="A",8,IF(K41="B+",7,IF(K41="B",6,IF(K41="C",5,IF(K41="RA",0,IF(K41="U",0,IF(K41="UA",0,0))))))))) -> 9 | AB41: =IF(L41="O",10,IF(L41="A+",9,IF(L41="A",8,IF(L41="B+",7,IF(L41="B",6,IF(L41="C",5,IF(L41="RA",0,IF(L41="U",0,IF(L41="UA",0,0))))))))) -> 8 | AC41: =IF(M41="O",10,IF(M41="A+",9,IF(M41="A",8,IF(M41="B+",7,IF(M41="B",6,IF(M41="C",5,IF(M41="RA",0,IF(M41="U",0,IF(M41="UA",0,0))))))))) -> 10 | AD41: =IF(N41="O",10,IF(N41="A+",9,IF(N41="A",8,IF(N41="B+",7,IF(N41="B",6,IF(N41="C",5,IF(N41="RA",0,IF(N41="U",0,IF(N41="UA",0,0))))))))) -> 7 | AG41: =(W41*W$7)+(X41*X$7)+(Y41*Y$7)+(Z41*Z$7)+(AA41*AA$7)+(AB41*AB$7)+(AC41*AC$7)+(AD41*AD$7) -> 200 | AH41: =IF(W41=0,0,W$7)+IF(X41=0,0,X$7)+IF(Y41=0,0,Y$7)+IF(Z41=0,0,Z$7)+IF(AA41=0,0,AA$7)+IF(AB41=0,0,AB$7)+IF(AC41=0,0,AC$7)+IF(AD41=0,0,AD$7) -> 23 | AI41: =IF(AH41=0,0,AG41/AH41) -> 8.6956522 | AJ41: =IF(AH41=23,"P","F") -> P | AK41: =IF(F41>179,1,0) -> 0 | AL41: =IF(F41>159,1,0)-AK41 -> 0 | AM41: =IF(F41>139,1,0)-(AK41+AL41) -> 0 | AN41: =IF(F41>119,1,0)-(AK41+AL41+AM41) -> 0 | AO41: =IF(F41>109,1,0)-(AK41+AL41+AM41+AN41) -> 0 | AP41: =IF(F41>=100,1,0)-(AK41+AL41+AM41+AN41+AO41) -> 0 | AQ41: =IF(F41<100,1,0) -> 1 | AS41: =IF(AK41=0,0,AJ41) -> 0 | AT41: =IF(AL41=0,0,AJ41) -> 0 | AU41: =IF(AM41=0,0,AJ41) -> 0 | AV41: =IF(AN41=0,0,AJ41) -> 0 | AW41: =IF(AO41=0,0,AJ41) -> 0 | AX41: =IF(AP41=0,0,AJ41) -> 0 | AY41: =IF(AQ41=0,0,AJ41) -> P | AZ41: =CONCATENATE(E41,D41) -> D | BA41: =CONCATENATE(AZ41,V41) -> DT | BB41: =IF(AZ41="HM",AJ41,"#") -> # | BC41: =IF(AZ41="HF",AJ41,"#") -> # | BD41: =IF(AZ41="DM",AJ41,"#") -> # | BE41: =IF(AZ41="DF",AJ41,"#") -> # | BG41: =IF(AZ41="HM",O41,"#") -> # | BH41: =IF(AZ41="HF",O41,"#") -> # | BI41: =IF(AZ41="DM",O41,"#") -> # | BJ41: =IF(AZ41="DF",O41,"#") -> # | BK41: =IF(D41="M",O41,"#") -> # | BL41: =IF(D41="F",O41,"#") -> # | BP41: =IF(BA41="HMT",AJ41,"#") -> # | BQ41: =IF(BA41="HFT",AJ41,"#") -> # | BR41: =IF(BA41="DMT",AJ41,"#") -> # | BS41: =IF(BA41="DFT",AJ41,"#") -> # | BT41: =IF(BA41="HMNT",AJ41,"#") -> # | BU41: =IF(BA41="HFNT",AJ41,"#") -> # | BV41: =IF(BA41="DMNT",AJ41,"#") -> # | BW41: =IF(BA41="DFNT",AJ41,"#") -> # | BY41: =IF(BA41="HMT",O41,"#") -> # | BZ41: =IF(BA41="HFT",O41,"#") -> # | CA41: =IF(BA41="DMT",O41,"#") -> # | CB41: =IF(BA41="DFT",O41,"#") -> # | CC41: =IF(BA41="HMNT",O41,"#") -> # | CD41: =IF(BA41="HFNT",O41,"#") -> # | CE41: =IF(BA41="DMNT",O41,"#") -> # | CF41: =IF(BA41="DFNT",O41,"#") -> # | CG41: =IF(D41="M",O41,"#") -> # | CH41: =IF(D41="F",O41,"#") -> # | CK41: =IF(W41=0,"EEP,"," ") | CL41: =IF(X41=0,"POC,"," ") | CM41: =IF(Y41=0,"DAV,"," ") | CN41: =IF(Z41=0,"EP,"," ") | CO41: =IF(AA41=0,"MAD,"," ") | CP41: =IF(AB41=0,"CCP,"," ") | CQ41: =IF(AC41=0,"UIUX,"," ") | CR41: =IF(AD41=0,"DEV,"," ") | CT41: =O41 -> 0 | CU41: =A41 -> 34 | CV41: =B41 -> 24IT0034 | CW41: =C41 -> E NITHYAPRABHA | CX41: =CONCATENATE(CK41,CL41,CM41,CN41,CO41,CP41,CQ41,CR41,CS41) | CY41: =CT41 -> 0 | DA41: =IF(E41="H",O41,"#") -> # | DB41: =IF(E41="D",O41,"#") -> 0
